<?xml version="1.0" ?>
<!-- =================================================================================== -->
<!-- |    This document was autogenerated by xacro from phantomx.xacro                 | -->
<!-- |    EDITING THIS FILE BY HAND IS NOT RECOMMENDED                                 | -->
<!-- =================================================================================== -->
<robot name="PhantomX" xmlns:xacro="http://www.ros.org/wiki/xacro">
  <link name="base_link"/>
  <joint name="j_phantomx_attachment" type="fixed">
    <parent link="base_link"/>
    <child link="MP_BODY"/>
    <origin rpy="0 0 0" xyz="0 0 0"/>
  </joint>
  <link name="MP_BODY">
    <inertial>
      <origin xyz="0 0 0"/>
      <mass value="0.97559947"/>
      <inertia ixx="3.1081800" ixy="-0.25460189" ixz="2.0318174" iyy="6.3787776" iyz="0.16417863" izz="5.3316425"/>
    </inertial>
    <visual>
      <!--origin xyz="-0.0235 0 -0.03525" rpy="0 0 0" /-->
      <origin rpy="0 0 0" xyz="0 0 0"/>
      <geometry>
        <!--box size="0.102 0.109 0.106" /-->
        <mesh filename="package://phantomx_description/meshes_mk3/body.STL" scale="1 1 1"/>
      </geometry>
      <material name="Grey">
        <color rgba="0.20 0.20 0.20 1.0"/>
      </material>
    </visual>
    <collision>
      <origin rpy="0 0 0" xyz="0 0 0"/>
      <geometry>
        <mesh filename="package://phantomx_description/meshes_mk3/body_coll.STL" scale="1 1 1"/>
      </geometry>
    </collision>
  </link>
  <gazebo reference="MP_BODY">
    <material>Gazebo/Black</material>
    <gravity>True</gravity>
  </gazebo>
  <link name="c1_AR">
    <inertial>
      <origin rpy="0 0 0" xyz="0 -0.02633 0"/>
      <mass value="0.024357719"/>
      <inertia ixx="0.0051411124" ixy="-0.00057530255" ixz="-0.000024729049" iyy="0.0081915737" iyz="-0.000019223094" izz="0.0011379812"/>
    </inertial>
    <visual>
      <origin rpy="0 0 0" xyz="0 -0.0252 0"/>
      <geometry>
        <!--box size="0.045 0.022 0.0325" /-->
        <mesh filename="package://phantomx_description/meshes_mk3/connect.STL" scale="1 1 1"/>
      </geometry>
      <material name="Grey">
        <color rgba="0.20 0.20 0.20 1.0"/>
      </material>
    </visual>
    <collision>
      <origin rpy="0 0 0" xyz="0 -0.02633 0"/>
      <geometry>
        <mesh filename="package://phantomx_description/meshes_mk3/connect_coll.STL" scale="1 1 1"/>
      </geometry>
    </collision>
  </link>
  <link name="c2_AR">
    <inertial>
      <origin rpy="0 0 0" xyz="0 -0.02633 0"/>
      <mass value="0.024357719"/>
      <inertia ixx="0.0051411124" ixy="-0.00057530255" ixz="-0.000024729049" iyy="0.0081915737" iyz="-0.000019223094" izz="0.0011379812"/>
    </inertial>
    <visual>
      <origin rpy="0 0 0" xyz="0 -0.0252 0"/>
      <geometry>
        <!--box size="0.045 0.022 0.0325" /-->
        <mesh filename="package://phantomx_description/meshes_mk3/connect.STL" scale="1 1 1"/>
      </geometry>
      <material name="Grey">
        <color rgba="0.20 0.20 0.20 1.0"/>
      </material>
    </visual>
    <collision>
      <origin rpy="0 0 0" xyz="0 -0.02633 0"/>
      <geometry>
        <mesh filename="package://phantomx_description/meshes_mk3/connect_coll.STL" scale="1 1 1"/>
      </geometry>
    </collision>
  </link>
  <link name="thigh_AR">
    <inertial>
      <origin rpy="0 0 0" xyz="0 0 0"/>
      <mass value="0.024357719"/>
      <inertia ixx="0.0051411124" ixy="-0.00057530255" ixz="-0.000024729049" iyy="0.0081915737" iyz="-0.000019223094" izz="0.0011379812"/>
    </inertial>
    <visual>
      <origin rpy="0 0 0" xyz="0 0 0"/>
      <geometry>
        <!--box size="0.045 0.022 0.0325" /-->
        <mesh filename="package://phantomx_description/meshes_mk3/thigh_l.STL" scale="1 1 1"/>
      </geometry>
      <material name="Grey">
        <color rgba="0.20 0.20 0.20 1.0"/>
      </material>
    </visual>
    <collision>
      <origin rpy="0 0 0" xyz="0 0 0"/>
      <geometry>
        <mesh filename="package://phantomx_description/meshes_mk3/thigh_l_coll.STL" scale="1 1 1"/>
      </geometry>
    </collision>
  </link>
  <link name="tibia_AR">
    <inertial>
      <origin rpy="0 0 0" xyz="0 0 0"/>
      <mass value="0.024357719"/>
      <inertia ixx="0.0051411124" ixy="-0.00057530255" ixz="-0.000024729049" iyy="0.0081915737" iyz="-0.000019223094" izz="0.0011379812"/>
    </inertial>
    <visual>
      <origin rpy="0 0 0" xyz="0 0 0"/>
      <geometry>
        <!--box size="0.045 0.022 0.0325" /-->
        <mesh filename="package://phantomx_description/meshes_mk3/tibia_l.STL" scale="1 1 1"/>
      </geometry>
      <material name="Grey">
        <color rgba="0.20 0.20 0.20 1.0"/>
      </material>
    </visual>
    <collision>
      <origin rpy="0 0 0" xyz="0 0 0"/>
      <geometry>
        <mesh filename="package://phantomx_description/meshes_mk3/tibia_l_coll.STL" scale="1 1 1"/>
      </geometry>
    </collision>
  </link>
  <link name="foot_AR">
    <visual>
      <origin rpy="0 0 0" xyz="0 0 0"/>
      <geometry>
        <sphere radius="0.003"/>
      </geometry>
    </visual>
    <collision>
      <origin rpy="0 0 0" xyz="0 0 0"/>
      <geometry>
        <box size="0.01 0.01 0.01"/>
      </geometry>
    </collision>
  </link>
  <joint name="AR_coxa_joint" type="revolute">
    <parent link="MP_BODY"/>
    <child link="c1_AR"/>
    <origin rpy="0 4.7123 0.7853981633974483" xyz="0.1248 -0.06164  0.001116"/>
    <axis xyz="1 0 0"/>
    <limit effort="2.8" lower="-2.6179939" upper="2.6179939" velocity="5.6548668"/>
    <dynamics damping="0.0" friction="0.7"/>
    <safety_controller k_position="100" k_velocity="1.5" soft_lower_limit="-2.6179939" soft_upper_limit="2.6179939"/>
  </joint>
  <joint name="j_c2_AR" type="fixed">
    <parent link="c1_AR"/>
    <child link="c2_AR"/>
    <origin rpy="0 1.5704 3.14159" xyz="0 -0.054 0"/>
    <safety_controller k_position="100" k_velocity="1.5" soft_lower_limit="0" soft_upper_limit="0"/>
  </joint>
  <joint name="AR_femur_joint" type="revolute">
    <parent link="c2_AR"/>
    <child link="thigh_AR"/>
    <origin rpy=" 0 3.14159 3.14159" xyz="0 0 0"/>
    <axis xyz="-1 0 0"/>
    <limit effort="2.8" lower="-2.6179939" upper="2.6179939" velocity="5.6548668"/>
    <dynamics damping="0.0" friction="0.7"/>
    <safety_controller k_position="100" k_velocity="1.5" soft_lower_limit="-2.6179939" soft_upper_limit="2.6179939"/>
  </joint>
  <joint name="AR_tibia_joint" type="revolute">
    <parent link="thigh_AR"/>
    <child link="tibia_AR"/>
    <origin rpy="-1.5707 0 3.14159" xyz="0 -0.0645 -0.0145"/>
    <axis xyz="-1 0 0"/>
    <limit effort="2.8" lower="-2.6179939" upper="2.6179939" velocity="5.6548668"/>
    <dynamics damping="0.0" friction="0.7"/>
    <safety_controller k_position="100" k_velocity="1.5" soft_lower_limit="-2.6179939" soft_upper_limit="2.6179939"/>
  </joint>
  <joint name="AR_foot_joint" type="fixed">
    <parent link="tibia_AR"/>
    <child link="foot_AR"/>
    <origin xyz="0 0.16 0.03"/>
    <safety_controller k_position="100" k_velocity="1.5" soft_lower_limit="0" soft_upper_limit="0"/>
  </joint>
  <transmission name="t_c1_AR">
    <type>transmission_interface/SimpleTransmission</type>
    <joint name="AR_coxa_joint">
      <hardwareInterface>hardware_interface/EffortJointInterface</hardwareInterface>
    </joint>
    <actuator name="m_c1_AR">
      <hardwareInterface>hardware_interface/EffortJointInterface</hardwareInterface>
      <mechanicalReduction>50</mechanicalReduction>
    </actuator>
  </transmission>
  <transmission name="t_thigh_AR">
    <type>transmission_interface/SimpleTransmission</type>
    <joint name="AR_femur_joint">
      <hardwareInterface>hardware_interface/EffortJointInterface</hardwareInterface>
    </joint>
    <actuator name="m_thigh_AR">
      <hardwareInterface>hardware_interface/EffortJointInterface</hardwareInterface>
      <mechanicalReduction>50</mechanicalReduction>
    </actuator>
  </transmission>
  <transmission name="t_tibia_AR">
    <type>transmission_interface/SimpleTransmission</type>
    <joint name="AR_tibia_joint">
      <hardwareInterface>hardware_interface/EffortJointInterface</hardwareInterface>
    </joint>
    <actuator name="m_tibia_AR">
      <hardwareInterface>hardware_interface/EffortJointInterface</hardwareInterface>
      <mechanicalReduction>50</mechanicalReduction>
    </actuator>
  </transmission>
  <gazebo reference="c1_AR">
    <material>Gazebo/Black</material>
    <mu1>0.8</mu1>
    <mu2>0.6</mu2>
    <kp>100</kp>
    <kd>10</kd>
    <gravity>True</gravity>
  </gazebo>
  <gazebo reference="c2_AR">
    <material>Gazebo/Black</material>
    <mu1>0.8</mu1>
    <mu2>0.6</mu2>
    <kp>100</kp>
    <kd>10</kd>
    <gravity>True</gravity>
  </gazebo>
  <gazebo reference="thigh_AR">
    <material>Gazebo/Black</material>
    <mu1>0.8</mu1>
    <mu2>0.6</mu2>
    <kp>100</kp>
    <kd>10</kd>
    <gravity>True</gravity>
  </gazebo>
  <gazebo reference="tibia_AR">
    <material>Gazebo/Black</material>
    <mu1>0.8</mu1>
    <mu2>0.6</mu2>
    <kp>1000</kp>
    <kd>10</kd>
    <gravity>True</gravity>
  </gazebo>
  <gazebo reference="foot_AR">
    <material>Gazebo/Blue</material>
    <mu1>0.8</mu1>
    <mu2>0.6</mu2>
    <kp>1000</kp>
    <kd>100</kd>
    <gravity>True</gravity>
    <sensor name="AR_foot_contact_sensor" type="contact">
      <always_on>true</always_on>
      <update_rate>1</update_rate>
      <contact>
        <collision>foot_AR_collision</collision>
      </contact>
      <plugin filename="libgazebo_ros_bumper.so" name="gripper_bumper">
        <bumperTopicName>AR_foot_contact_sensor_state</bumperTopicName>
        <frameName>AR_foot</frameName>
      </plugin>
    </sensor>
  </gazebo>
  <link name="c1_BR">
    <inertial>
      <origin rpy="0 0 0" xyz="0 -0.02633 0"/>
      <mass value="0.024357719"/>
      <inertia ixx="0.0051411124" ixy="-0.00057530255" ixz="-0.000024729049" iyy="0.0081915737" iyz="-0.000019223094" izz="0.0011379812"/>
    </inertial>
    <visual>
      <origin rpy="0 0 0" xyz="0 -0.0252 0"/>
      <geometry>
        <!--box size="0.045 0.022 0.0325" /-->
        <mesh filename="package://phantomx_description/meshes_mk3/connect.STL" scale="1 1 1"/>
      </geometry>
      <material name="Grey">
        <color rgba="0.20 0.20 0.20 1.0"/>
      </material>
    </visual>
    <collision>
      <origin rpy="0 0 0" xyz="0 -0.02633 0"/>
      <geometry>
        <mesh filename="package://phantomx_description/meshes_mk3/connect_coll.STL" scale="1 1 1"/>
      </geometry>
    </collision>
  </link>
  <link name="c2_BR">
    <inertial>
      <origin rpy="0 0 0" xyz="0 -0.02633 0"/>
      <mass value="0.024357719"/>
      <inertia ixx="0.0051411124" ixy="-0.00057530255" ixz="-0.000024729049" iyy="0.0081915737" iyz="-0.000019223094" izz="0.0011379812"/>
    </inertial>
    <visual>
      <origin rpy="0 0 0" xyz="0 -0.0252 0"/>
      <geometry>
        <!--box size="0.045 0.022 0.0325" /-->
        <mesh filename="package://phantomx_description/meshes_mk3/connect.STL" scale="1 1 1"/>
      </geometry>
      <material name="Grey">
        <color rgba="0.20 0.20 0.20 1.0"/>
      </material>
    </visual>
    <collision>
      <origin rpy="0 0 0" xyz="0 -0.02633 0"/>
      <geometry>
        <mesh filename="package://phantomx_description/meshes_mk3/connect_coll.STL" scale="1 1 1"/>
      </geometry>
    </collision>
  </link>
  <link name="thigh_BR">
    <inertial>
      <origin rpy="0 0 0" xyz="0 0 0"/>
      <mass value="0.024357719"/>
      <inertia ixx="0.0051411124" ixy="-0.00057530255" ixz="-0.000024729049" iyy="0.0081915737" iyz="-0.000019223094" izz="0.0011379812"/>
    </inertial>
    <visual>
      <origin rpy="0 0 0" xyz="0 0 0"/>
      <geometry>
        <!--box size="0.045 0.022 0.0325" /-->
        <mesh filename="package://phantomx_description/meshes_mk3/thigh_l.STL" scale="1 1 1"/>
      </geometry>
      <material name="Grey">
        <color rgba="0.20 0.20 0.20 1.0"/>
      </material>
    </visual>
    <collision>
      <origin rpy="0 0 0" xyz="0 0 0"/>
      <geometry>
        <mesh filename="package://phantomx_description/meshes_mk3/thigh_l_coll.STL" scale="1 1 1"/>
      </geometry>
    </collision>
  </link>
  <link name="tibia_BR">
    <inertial>
      <origin rpy="0 0 0" xyz="0 0 0"/>
      <mass value="0.024357719"/>
      <inertia ixx="0.0051411124" ixy="-0.00057530255" ixz="-0.000024729049" iyy="0.0081915737" iyz="-0.000019223094" izz="0.0011379812"/>
    </inertial>
    <visual>
      <origin rpy="0 0 0" xyz="0 0 0"/>
      <geometry>
        <!--box size="0.045 0.022 0.0325" /-->
        <mesh filename="package://phantomx_description/meshes_mk3/tibia_l.STL" scale="1 1 1"/>
      </geometry>
      <material name="Grey">
        <color rgba="0.20 0.20 0.20 1.0"/>
      </material>
    </visual>
    <collision>
      <origin rpy="0 0 0" xyz="0 0 0"/>
      <geometry>
        <mesh filename="package://phantomx_description/meshes_mk3/tibia_l_coll.STL" scale="1 1 1"/>
      </geometry>
    </collision>
  </link>
  <link name="foot_BR">
    <visual>
      <origin rpy="0 0 0" xyz="0 0 0"/>
      <geometry>
        <sphere radius="0.003"/>
      </geometry>
    </visual>
    <collision>
      <origin rpy="0 0 0" xyz="0 0 0"/>
      <geometry>
        <box size="0.01 0.01 0.01"/>
      </geometry>
    </collision>
  </link>
  <joint name="BR_coxa_joint" type="revolute">
    <parent link="MP_BODY"/>
    <child link="c1_BR"/>
    <origin rpy="0 4.7123 0" xyz="0 -0.1034  0.001116"/>
    <axis xyz="1 0 0"/>
    <limit effort="2.8" lower="-2.6179939" upper="2.6179939" velocity="5.6548668"/>
    <dynamics damping="0.0" friction="0.7"/>
    <safety_controller k_position="100" k_velocity="1.5" soft_lower_limit="-2.6179939" soft_upper_limit="2.6179939"/>
  </joint>
  <joint name="j_c2_BR" type="fixed">
    <parent link="c1_BR"/>
    <child link="c2_BR"/>
    <origin rpy="0 1.5704 3.14159" xyz="0 -0.054 0"/>
    <safety_controller k_position="100" k_velocity="1.5" soft_lower_limit="0" soft_upper_limit="0"/>
  </joint>
  <joint name="BR_femur_joint" type="revolute">
    <parent link="c2_BR"/>
    <child link="thigh_BR"/>
    <origin rpy=" 0 3.14159 3.14159" xyz="0 0 0"/>
    <axis xyz="-1 0 0"/>
    <limit effort="2.8" lower="-2.6179939" upper="2.6179939" velocity="5.6548668"/>
    <dynamics damping="0.0" friction="0.7"/>
    <safety_controller k_position="100" k_velocity="1.5" soft_lower_limit="-2.6179939" soft_upper_limit="2.6179939"/>
  </joint>
  <joint name="BR_tibia_joint" type="revolute">
    <parent link="thigh_BR"/>
    <child link="tibia_BR"/>
    <origin rpy="-1.5707 0 3.14159" xyz="0 -0.0645 -0.0145"/>
    <axis xyz="-1 0 0"/>
    <limit effort="2.8" lower="-2.6179939" upper="2.6179939" velocity="5.6548668"/>
    <dynamics damping="0.0" friction="0.7"/>
    <safety_controller k_position="100" k_velocity="1.5" soft_lower_limit="-2.6179939" soft_upper_limit="2.6179939"/>
  </joint>
  <joint name="BR_foot_joint" type="fixed">
    <parent link="tibia_BR"/>
    <child link="foot_BR"/>
    <origin xyz="0 0.16 0.03"/>
    <safety_controller k_position="100" k_velocity="1.5" soft_lower_limit="0" soft_upper_limit="0"/>
  </joint>
  <transmission name="t_c1_BR">
    <type>transmission_interface/SimpleTransmission</type>
    <joint name="BR_coxa_joint">
      <hardwareInterface>hardware_interface/EffortJointInterface</hardwareInterface>
    </joint>
    <actuator name="m_c1_BR">
      <hardwareInterface>hardware_interface/EffortJointInterface</hardwareInterface>
      <mechanicalReduction>50</mechanicalReduction>
    </actuator>
  </transmission>
  <transmission name="t_thigh_BR">
    <type>transmission_interface/SimpleTransmission</type>
    <joint name="BR_femur_joint">
      <hardwareInterface>hardware_interface/EffortJointInterface</hardwareInterface>
    </joint>
    <actuator name="m_thigh_BR">
      <hardwareInterface>hardware_interface/EffortJointInterface</hardwareInterface>
      <mechanicalReduction>50</mechanicalReduction>
    </actuator>
  </transmission>
  <transmission name="t_tibia_BR">
    <type>transmission_interface/SimpleTransmission</type>
    <joint name="BR_tibia_joint">
      <hardwareInterface>hardware_interface/EffortJointInterface</hardwareInterface>
    </joint>
    <actuator name="m_tibia_BR">
      <hardwareInterface>hardware_interface/EffortJointInterface</hardwareInterface>
      <mechanicalReduction>50</mechanicalReduction>
    </actuator>
  </transmission>
  <gazebo reference="c1_BR">
    <material>Gazebo/Black</material>
    <mu1>0.8</mu1>
    <mu2>0.6</mu2>
    <kp>100</kp>
    <kd>10</kd>
    <gravity>True</gravity>
  </gazebo>
  <gazebo reference="c2_BR">
    <material>Gazebo/Black</material>
    <mu1>0.8</mu1>
    <mu2>0.6</mu2>
    <kp>100</kp>
    <kd>10</kd>
    <gravity>True</gravity>
  </gazebo>
  <gazebo reference="thigh_BR">
    <material>Gazebo/Black</material>
    <mu1>0.8</mu1>
    <mu2>0.6</mu2>
    <kp>100</kp>
    <kd>10</kd>
    <gravity>True</gravity>
  </gazebo>
  <gazebo reference="tibia_BR">
    <material>Gazebo/Black</material>
    <mu1>0.8</mu1>
    <mu2>0.6</mu2>
    <kp>1000</kp>
    <kd>10</kd>
    <gravity>True</gravity>
  </gazebo>
  <gazebo reference="foot_BR">
    <material>Gazebo/Blue</material>
    <mu1>0.8</mu1>
    <mu2>0.6</mu2>
    <kp>1000</kp>
    <kd>100</kd>
    <gravity>True</gravity>
    <sensor name="BR_foot_contact_sensor" type="contact">
      <always_on>true</always_on>
      <update_rate>1</update_rate>
      <contact>
        <collision>foot_BR_collision</collision>
      </contact>
      <plugin filename="libgazebo_ros_bumper.so" name="gripper_bumper">
        <bumperTopicName>BR_foot_contact_sensor_state</bumperTopicName>
        <frameName>BR_foot</frameName>
      </plugin>
    </sensor>
  </gazebo>
  <link name="c1_CR">
    <inertial>
      <origin rpy="0 0 0" xyz="0 -0.02633 0"/>
      <mass value="0.024357719"/>
      <inertia ixx="0.0051411124" ixy="-0.00057530255" ixz="-0.000024729049" iyy="0.0081915737" iyz="-0.000019223094" izz="0.0011379812"/>
    </inertial>
    <visual>
      <origin rpy="0 0 0" xyz="0 -0.0252 0"/>
      <geometry>
        <!--box size="0.045 0.022 0.0325" /-->
        <mesh filename="package://phantomx_description/meshes_mk3/connect.STL" scale="1 1 1"/>
      </geometry>
      <material name="Grey">
        <color rgba="0.20 0.20 0.20 1.0"/>
      </material>
    </visual>
    <collision>
      <origin rpy="0 0 0" xyz="0 -0.02633 0"/>
      <geometry>
        <mesh filename="package://phantomx_description/meshes_mk3/connect_coll.STL" scale="1 1 1"/>
      </geometry>
    </collision>
  </link>
  <link name="c2_CR">
    <inertial>
      <origin rpy="0 0 0" xyz="0 -0.02633 0"/>
      <mass value="0.024357719"/>
      <inertia ixx="0.0051411124" ixy="-0.00057530255" ixz="-0.000024729049" iyy="0.0081915737" iyz="-0.000019223094" izz="0.0011379812"/>
    </inertial>
    <visual>
      <origin rpy="0 0 0" xyz="0 -0.0252 0"/>
      <geometry>
        <!--box size="0.045 0.022 0.0325" /-->
        <mesh filename="package://phantomx_description/meshes_mk3/connect.STL" scale="1 1 1"/>
      </geometry>
      <material name="Grey">
        <color rgba="0.20 0.20 0.20 1.0"/>
      </material>
    </visual>
    <collision>
      <origin rpy="0 0 0" xyz="0 -0.02633 0"/>
      <geometry>
        <mesh filename="package://phantomx_description/meshes_mk3/connect_coll.STL" scale="1 1 1"/>
      </geometry>
    </collision>
  </link>
  <link name="thigh_CR">
    <inertial>
      <origin rpy="0 0 0" xyz="0 0 0"/>
      <mass value="0.024357719"/>
      <inertia ixx="0.0051411124" ixy="-0.00057530255" ixz="-0.000024729049" iyy="0.0081915737" iyz="-0.000019223094" izz="0.0011379812"/>
    </inertial>
    <visual>
      <origin rpy="0 0 0" xyz="0 0 0"/>
      <geometry>
        <!--box size="0.045 0.022 0.0325" /-->
        <mesh filename="package://phantomx_description/meshes_mk3/thigh_l.STL" scale="1 1 1"/>
      </geometry>
      <material name="Grey">
        <color rgba="0.20 0.20 0.20 1.0"/>
      </material>
    </visual>
    <collision>
      <origin rpy="0 0 0" xyz="0 0 0"/>
      <geometry>
        <mesh filename="package://phantomx_description/meshes_mk3/thigh_l_coll.STL" scale="1 1 1"/>
      </geometry>
    </collision>
  </link>
  <link name="tibia_CR">
    <inertial>
      <origin rpy="0 0 0" xyz="0 0 0"/>
      <mass value="0.024357719"/>
      <inertia ixx="0.0051411124" ixy="-0.00057530255" ixz="-0.000024729049" iyy="0.0081915737" iyz="-0.000019223094" izz="0.0011379812"/>
    </inertial>
    <visual>
      <origin rpy="0 0 0" xyz="0 0 0"/>
      <geometry>
        <!--box size="0.045 0.022 0.0325" /-->
        <mesh filename="package://phantomx_description/meshes_mk3/tibia_l.STL" scale="1 1 1"/>
      </geometry>
      <material name="Grey">
        <color rgba="0.20 0.20 0.20 1.0"/>
      </material>
    </visual>
    <collision>
      <origin rpy="0 0 0" xyz="0 0 0"/>
      <geometry>
        <mesh filename="package://phantomx_description/meshes_mk3/tibia_l_coll.STL" scale="1 1 1"/>
      </geometry>
    </collision>
  </link>
  <link name="foot_CR">
    <visual>
      <origin rpy="0 0 0" xyz="0 0 0"/>
      <geometry>
        <sphere radius="0.003"/>
      </geometry>
    </visual>
    <collision>
      <origin rpy="0 0 0" xyz="0 0 0"/>
      <geometry>
        <box size="0.01 0.01 0.01"/>
      </geometry>
    </collision>
  </link>
  <joint name="CR_coxa_joint" type="revolute">
    <parent link="MP_BODY"/>
    <child link="c1_CR"/>
    <origin rpy="0 4.7123 -0.7853981633974483" xyz="-0.1248 -0.06164  0.001116"/>
    <axis xyz="1 0 0"/>
    <limit effort="2.8" lower="-2.6179939" upper="2.6179939" velocity="5.6548668"/>
    <dynamics damping="0.0" friction="0.7"/>
    <safety_controller k_position="100" k_velocity="1.5" soft_lower_limit="-2.6179939" soft_upper_limit="2.6179939"/>
  </joint>
  <joint name="j_c2_CR" type="fixed">
    <parent link="c1_CR"/>
    <child link="c2_CR"/>
    <origin rpy="0 1.5704 3.14159" xyz="0 -0.054 0"/>
    <safety_controller k_position="100" k_velocity="1.5" soft_lower_limit="0" soft_upper_limit="0"/>
  </joint>
  <joint name="CR_femur_joint" type="revolute">
    <parent link="c2_CR"/>
    <child link="thigh_CR"/>
    <origin rpy=" 0 3.14159 3.14159" xyz="0 0 0"/>
    <axis xyz="-1 0 0"/>
    <limit effort="2.8" lower="-2.6179939" upper="2.6179939" velocity="5.6548668"/>
    <dynamics damping="0.0" friction="0.7"/>
    <safety_controller k_position="100" k_velocity="1.5" soft_lower_limit="-2.6179939" soft_upper_limit="2.6179939"/>
  </joint>
  <joint name="CR_tibia_joint" type="revolute">
    <parent link="thigh_CR"/>
    <child link="tibia_CR"/>
    <origin rpy="-1.5707 0 3.14159" xyz="0 -0.0645 -0.0145"/>
    <axis xyz="-1 0 0"/>
    <limit effort="2.8" lower="-2.6179939" upper="2.6179939" velocity="5.6548668"/>
    <dynamics damping="0.0" friction="0.7"/>
    <safety_controller k_position="100" k_velocity="1.5" soft_lower_limit="-2.6179939" soft_upper_limit="2.6179939"/>
  </joint>
  <joint name="CR_foot_joint" type="fixed">
    <parent link="tibia_CR"/>
    <child link="foot_CR"/>
    <origin xyz="0 0.16 0.03"/>
    <safety_controller k_position="100" k_velocity="1.5" soft_lower_limit="0" soft_upper_limit="0"/>
  </joint>
  <transmission name="t_c1_CR">
    <type>transmission_interface/SimpleTransmission</type>
    <joint name="CR_coxa_joint">
      <hardwareInterface>hardware_interface/EffortJointInterface</hardwareInterface>
    </joint>
    <actuator name="m_c1_CR">
      <hardwareInterface>hardware_interface/EffortJointInterface</hardwareInterface>
      <mechanicalReduction>50</mechanicalReduction>
    </actuator>
  </transmission>
  <transmission name="t_thigh_CR">
    <type>transmission_interface/SimpleTransmission</type>
    <joint name="CR_femur_joint">
      <hardwareInterface>hardware_interface/EffortJointInterface</hardwareInterface>
    </joint>
    <actuator name="m_thigh_CR">
      <hardwareInterface>hardware_interface/EffortJointInterface</hardwareInterface>
      <mechanicalReduction>50</mechanicalReduction>
    </actuator>
  </transmission>
  <transmission name="t_tibia_CR">
    <type>transmission_interface/SimpleTransmission</type>
    <joint name="CR_tibia_joint">
      <hardwareInterface>hardware_interface/EffortJointInterface</hardwareInterface>
    </joint>
    <actuator name="m_tibia_CR">
      <hardwareInterface>hardware_interface/EffortJointInterface</hardwareInterface>
      <mechanicalReduction>50</mechanicalReduction>
    </actuator>
  </transmission>
  <gazebo reference="c1_CR">
    <material>Gazebo/Black</material>
    <mu1>0.8</mu1>
    <mu2>0.6</mu2>
    <kp>100</kp>
    <kd>10</kd>
    <gravity>True</gravity>
  </gazebo>
  <gazebo reference="c2_CR">
    <material>Gazebo/Black</material>
    <mu1>0.8</mu1>
    <mu2>0.6</mu2>
    <kp>100</kp>
    <kd>10</kd>
    <gravity>True</gravity>
  </gazebo>
  <gazebo reference="thigh_CR">
    <material>Gazebo/Black</material>
    <mu1>0.8</mu1>
    <mu2>0.6</mu2>
    <kp>100</kp>
    <kd>10</kd>
    <gravity>True</gravity>
  </gazebo>
  <gazebo reference="tibia_CR">
    <material>Gazebo/Black</material>
    <mu1>0.8</mu1>
    <mu2>0.6</mu2>
    <kp>1000</kp>
    <kd>10</kd>
    <gravity>True</gravity>
  </gazebo>
  <gazebo reference="foot_CR">
    <material>Gazebo/Blue</material>
    <mu1>0.8</mu1>
    <mu2>0.6</mu2>
    <kp>1000</kp>
    <kd>100</kd>
    <gravity>True</gravity>
    <sensor name="CR_foot_contact_sensor" type="contact">
      <always_on>true</always_on>
      <update_rate>1</update_rate>
      <contact>
        <collision>foot_CR_collision</collision>
      </contact>
      <plugin filename="libgazebo_ros_bumper.so" name="gripper_bumper">
        <bumperTopicName>CR_foot_contact_sensor_state</bumperTopicName>
        <frameName>CR_foot</frameName>
      </plugin>
    </sensor>
  </gazebo>
  <link name="c1_AL">
    <inertial>
      <origin rpy="0 0 0" xyz="0 -0.02633 0"/>
      <mass value="0.024357719"/>
      <inertia ixx="0.0051411124" ixy="-0.00057530255" ixz="-0.000024729049" iyy="0.0081915737" iyz="-0.000019223094" izz="0.0011379812"/>
    </inertial>
    <visual>
      <origin rpy="0 0 0" xyz="0 -0.0252 0"/>
      <geometry>
        <!--box size="0.045 0.022 0.0325" /-->
        <mesh filename="package://phantomx_description/meshes_mk3/connect.STL" scale="1 1 1"/>
      </geometry>
      <material name="Grey">
        <color rgba="0.20 0.20 0.20 1.0"/>
      </material>
    </visual>
    <collision>
      <origin rpy="0 0 0" xyz="0 -0.02633 0"/>
      <geometry>
        <mesh filename="package://phantomx_description/meshes_mk3/connect_coll.STL" scale="1 1 1"/>
      </geometry>
    </collision>
  </link>
  <link name="c2_AL">
    <inertial>
      <origin rpy="0 0 0" xyz="0 -0.02633 0"/>
      <mass value="0.024357719"/>
      <inertia ixx="0.0051411124" ixy="-0.00057530255" ixz="-0.000024729049" iyy="0.0081915737" iyz="-0.000019223094" izz="0.0011379812"/>
    </inertial>
    <visual>
      <origin rpy="0 0 0" xyz="0 -0.0252 0"/>
      <geometry>
        <!--box size="0.045 0.022 0.0325" /-->
        <mesh filename="package://phantomx_description/meshes_mk3/connect.STL" scale="1 1 1"/>
      </geometry>
      <material name="Grey">
        <color rgba="0.20 0.20 0.20 1.0"/>
      </material>
    </visual>
    <collision>
      <origin rpy="0 0 0" xyz="0 -0.02633 0"/>
      <geometry>
        <mesh filename="package://phantomx_description/meshes_mk3/connect_coll.STL" scale="1 1 1"/>
      </geometry>
    </collision>
  </link>
  <link name="thigh_AL">
    <inertial>
      <origin rpy="0 0 0" xyz="0 0 0"/>
      <mass value="0.024357719"/>
      <inertia ixx="0.0051411124" ixy="-0.00057530255" ixz="-0.000024729049" iyy="0.0081915737" iyz="-0.000019223094" izz="0.0011379812"/>
    </inertial>
    <visual>
      <origin rpy="0 0 0" xyz="0 0 0"/>
      <geometry>
        <!--box size="0.045 0.022 0.0325" /-->
        <mesh filename="package://phantomx_description/meshes_mk3/thigh_l.STL" scale="1 1 1"/>
      </geometry>
      <material name="Grey">
        <color rgba="0.20 0.20 0.20 1.0"/>
      </material>
    </visual>
    <collision>
      <origin rpy="0 0 0" xyz="0 0 0"/>
      <geometry>
        <mesh filename="package://phantomx_description/meshes_mk3/thigh_l_coll.STL" scale="1 1 1"/>
      </geometry>
    </collision>
  </link>
  <link name="tibia_AL">
    <inertial>
      <origin rpy="0 0 0" xyz="0 0 0"/>
      <mass value="0.024357719"/>
      <inertia ixx="0.0051411124" ixy="-0.00057530255" ixz="-0.000024729049" iyy="0.0081915737" iyz="-0.000019223094" izz="0.0011379812"/>
    </inertial>
    <visual>
      <origin rpy="0 0 0" xyz="0 0 0"/>
      <geometry>
        <!--box size="0.045 0.022 0.0325" /-->
        <mesh filename="package://phantomx_description/meshes_mk3/tibia_l.STL" scale="1 1 1"/>
      </geometry>
      <material name="Grey">
        <color rgba="0.20 0.20 0.20 1.0"/>
      </material>
    </visual>
    <collision>
      <origin rpy="0 0 0" xyz="0 0 0"/>
      <geometry>
        <mesh filename="package://phantomx_description/meshes_mk3/tibia_l_coll.STL" scale="1 1 1"/>
      </geometry>
    </collision>
  </link>
  <link name="foot_AL">
    <visual>
      <origin rpy="0 0 0" xyz="0 0 0"/>
      <geometry>
        <sphere radius="0.003"/>
      </geometry>
    </visual>
    <collision>
      <origin rpy="0 0 0" xyz="0 0 0"/>
      <geometry>
        <box size="0.01 0.01 0.01"/>
      </geometry>
    </collision>
  </link>
  <joint name="AL_coxa_joint" type="revolute">
    <parent link="MP_BODY"/>
    <child link="c1_AL"/>
    <origin rpy="0 4.7123 2.356194490192345" xyz="0.1248 0.06164  0.001116"/>
    <axis xyz="1 0 0"/>
    <limit effort="2.8" lower="-2.6179939" upper="2.6179939" velocity="5.6548668"/>
    <dynamics damping="0.0" friction="0.7"/>
    <safety_controller k_position="100" k_velocity="1.5" soft_lower_limit="-2.6179939" soft_upper_limit="2.6179939"/>
  </joint>
  <joint name="j_c2_AL" type="fixed">
    <parent link="c1_AL"/>
    <child link="c2_AL"/>
    <origin rpy="0 1.5704 3.14159" xyz="0 -0.054 0"/>
    <safety_controller k_position="100" k_velocity="1.5" soft_lower_limit="0" soft_upper_limit="0"/>
  </joint>
  <joint name="AL_femur_joint" type="revolute">
    <parent link="c2_AL"/>
    <child link="thigh_AL"/>
    <origin rpy=" 0 3.14159 3.14159" xyz="0 0 0"/>
    <axis xyz="1 0 0"/>
    <limit effort="2.8" lower="-2.6179939" upper="2.6179939" velocity="5.6548668"/>
    <dynamics damping="0.0" friction="0.7"/>
    <safety_controller k_position="100" k_velocity="1.5" soft_lower_limit="-2.6179939" soft_upper_limit="2.6179939"/>
  </joint>
  <joint name="AL_tibia_joint" type="revolute">
    <parent link="thigh_AL"/>
    <child link="tibia_AL"/>
    <origin rpy="-1.5707 0 3.14159" xyz="0 -0.0645 -0.0145"/>
    <axis xyz="1 0 0"/>
    <limit effort="2.8" lower="-2.6179939" upper="2.6179939" velocity="5.6548668"/>
    <dynamics damping="0.0" friction="0.7"/>
    <safety_controller k_position="100" k_velocity="1.5" soft_lower_limit="-2.6179939" soft_upper_limit="2.6179939"/>
  </joint>
  <joint name="AL_foot_joint" type="fixed">
    <parent link="tibia_AL"/>
    <child link="foot_AL"/>
    <origin xyz="0 0.16 0.03"/>
    <safety_controller k_position="100" k_velocity="1.5" soft_lower_limit="0" soft_upper_limit="0"/>
  </joint>
  <transmission name="t_c1_AL">
    <type>transmission_interface/SimpleTransmission</type>
    <joint name="AL_coxa_joint">
      <hardwareInterface>hardware_interface/EffortJointInterface</hardwareInterface>
    </joint>
    <actuator name="m_c1_AL">
      <hardwareInterface>hardware_interface/EffortJointInterface</hardwareInterface>
      <mechanicalReduction>50</mechanicalReduction>
    </actuator>
  </transmission>
  <transmission name="t_thigh_AL">
    <type>transmission_interface/SimpleTransmission</type>
    <joint name="AL_femur_joint">
      <hardwareInterface>hardware_interface/EffortJointInterface</hardwareInterface>
    </joint>
    <actuator name="m_thigh_AL">
      <hardwareInterface>hardware_interface/EffortJointInterface</hardwareInterface>
      <mechanicalReduction>50</mechanicalReduction>
    </actuator>
  </transmission>
  <transmission name="t_tibia_AL">
    <type>transmission_interface/SimpleTransmission</type>
    <joint name="AL_tibia_joint">
      <hardwareInterface>hardware_interface/EffortJointInterface</hardwareInterface>
    </joint>
    <actuator name="m_tibia_AL">
      <hardwareInterface>hardware_interface/EffortJointInterface</hardwareInterface>
      <mechanicalReduction>50</mechanicalReduction>
    </actuator>
  </transmission>
  <gazebo reference="c1_AL">
    <material>Gazebo/Black</material>
    <mu1>0.8</mu1>
    <mu2>0.6</mu2>
    <kp>100</kp>
    <kd>10</kd>
    <gravity>True</gravity>
  </gazebo>
  <gazebo reference="c2_AL">
    <material>Gazebo/Black</material>
    <mu1>0.8</mu1>
    <mu2>0.6</mu2>
    <kp>100</kp>
    <kd>10</kd>
    <gravity>True</gravity>
  </gazebo>
  <gazebo reference="thigh_AL">
    <material>Gazebo/Black</material>
    <mu1>0.8</mu1>
    <mu2>0.6</mu2>
    <kp>100</kp>
    <kd>10</kd>
    <gravity>True</gravity>
  </gazebo>
  <gazebo reference="tibia_AL">
    <material>Gazebo/Black</material>
    <mu1>0.8</mu1>
    <mu2>0.6</mu2>
    <kp>1000</kp>
    <kd>10</kd>
    <gravity>True</gravity>
  </gazebo>
  <gazebo reference="foot_AL">
    <material>Gazebo/Blue</material>
    <mu1>0.8</mu1>
    <mu2>0.6</mu2>
    <kp>1000</kp>
    <kd>100</kd>
    <gravity>True</gravity>
    <sensor name="AL_foot_contact_sensor" type="contact">
      <always_on>true</always_on>
      <update_rate>1</update_rate>
      <contact>
        <collision>foot_AL_collision</collision>
      </contact>
      <plugin filename="libgazebo_ros_bumper.so" name="gripper_bumper">
        <bumperTopicName>AL_foot_contact_sensor_state</bumperTopicName>
        <frameName>AL_foot</frameName>
      </plugin>
    </sensor>
  </gazebo>
  <link name="c1_BL">
    <inertial>
      <origin rpy="0 0 0" xyz="0 -0.02633 0"/>
      <mass value="0.024357719"/>
      <inertia ixx="0.0051411124" ixy="-0.00057530255" ixz="-0.000024729049" iyy="0.0081915737" iyz="-0.000019223094" izz="0.0011379812"/>
    </inertial>
    <visual>
      <origin rpy="0 0 0" xyz="0 -0.0252 0"/>
      <geometry>
        <!--box size="0.045 0.022 0.0325" /-->
        <mesh filename="package://phantomx_description/meshes_mk3/connect.STL" scale="1 1 1"/>
      </geometry>
      <material name="Grey">
        <color rgba="0.20 0.20 0.20 1.0"/>
      </material>
    </visual>
    <collision>
      <origin rpy="0 0 0" xyz="0 -0.02633 0"/>
      <geometry>
        <mesh filename="package://phantomx_description/meshes_mk3/connect_coll.STL" scale="1 1 1"/>
      </geometry>
    </collision>
  </link>
  <link name="c2_BL">
    <inertial>
      <origin rpy="0 0 0" xyz="0 -0.02633 0"/>
      <mass value="0.024357719"/>
      <inertia ixx="0.0051411124" ixy="-0.00057530255" ixz="-0.000024729049" iyy="0.0081915737" iyz="-0.000019223094" izz="0.0011379812"/>
    </inertial>
    <visual>
      <origin rpy="0 0 0" xyz="0 -0.0252 0"/>
      <geometry>
        <!--box size="0.045 0.022 0.0325" /-->
        <mesh filename="package://phantomx_description/meshes_mk3/connect.STL" scale="1 1 1"/>
      </geometry>
      <material name="Grey">
        <color rgba="0.20 0.20 0.20 1.0"/>
      </material>
    </visual>
    <collision>
      <origin rpy="0 0 0" xyz="0 -0.02633 0"/>
      <geometry>
        <mesh filename="package://phantomx_description/meshes_mk3/connect_coll.STL" scale="1 1 1"/>
      </geometry>
    </collision>
  </link>
  <link name="thigh_BL">
    <inertial>
      <origin rpy="0 0 0" xyz="0 0 0"/>
      <mass value="0.024357719"/>
      <inertia ixx="0.0051411124" ixy="-0.00057530255" ixz="-0.000024729049" iyy="0.0081915737" iyz="-0.000019223094" izz="0.0011379812"/>
    </inertial>
    <visual>
      <origin rpy="0 0 0" xyz="0 0 0"/>
      <geometry>
        <!--box size="0.045 0.022 0.0325" /-->
        <mesh filename="package://phantomx_description/meshes_mk3/thigh_l.STL" scale="1 1 1"/>
      </geometry>
      <material name="Grey">
        <color rgba="0.20 0.20 0.20 1.0"/>
      </material>
    </visual>
    <collision>
      <origin rpy="0 0 0" xyz="0 0 0"/>
      <geometry>
        <mesh filename="package://phantomx_description/meshes_mk3/thigh_l_coll.STL" scale="1 1 1"/>
      </geometry>
    </collision>
  </link>
  <link name="tibia_BL">
    <inertial>
      <origin rpy="0 0 0" xyz="0 0 0"/>
      <mass value="0.024357719"/>
      <inertia ixx="0.0051411124" ixy="-0.00057530255" ixz="-0.000024729049" iyy="0.0081915737" iyz="-0.000019223094" izz="0.0011379812"/>
    </inertial>
    <visual>
      <origin rpy="0 0 0" xyz="0 0 0"/>
      <geometry>
        <!--box size="0.045 0.022 0.0325" /-->
        <mesh filename="package://phantomx_description/meshes_mk3/tibia_l.STL" scale="1 1 1"/>
      </geometry>
      <material name="Grey">
        <color rgba="0.20 0.20 0.20 1.0"/>
      </material>
    </visual>
    <collision>
      <origin rpy="0 0 0" xyz="0 0 0"/>
      <geometry>
        <mesh filename="package://phantomx_description/meshes_mk3/tibia_l_coll.STL" scale="1 1 1"/>
      </geometry>
    </collision>
  </link>
  <link name="foot_BL">
    <visual>
      <origin rpy="0 0 0" xyz="0 0 0"/>
      <geometry>
        <sphere radius="0.003"/>
      </geometry>
    </visual>
    <collision>
      <origin rpy="0 0 0" xyz="0 0 0"/>
      <geometry>
        <box size="0.01 0.01 0.01"/>
      </geometry>
    </collision>
  </link>
  <joint name="BL_coxa_joint" type="revolute">
    <parent link="MP_BODY"/>
    <child link="c1_BL"/>
    <origin rpy="0 4.7123 3.14159" xyz="0 0.1034  0.001116"/>
    <axis xyz="1 0 0"/>
    <limit effort="2.8" lower="-2.6179939" upper="2.6179939" velocity="5.6548668"/>
    <dynamics damping="0.0" friction="0.7"/>
    <safety_controller k_position="100" k_velocity="1.5" soft_lower_limit="-2.6179939" soft_upper_limit="2.6179939"/>
  </joint>
  <joint name="j_c2_BL" type="fixed">
    <parent link="c1_BL"/>
    <child link="c2_BL"/>
    <origin rpy="0 1.5704 3.14159" xyz="0 -0.054 0"/>
    <safety_controller k_position="100" k_velocity="1.5" soft_lower_limit="0" soft_upper_limit="0"/>
  </joint>
  <joint name="BL_femur_joint" type="revolute">
    <parent link="c2_BL"/>
    <child link="thigh_BL"/>
    <origin rpy=" 0 3.14159 3.14159" xyz="0 0 0"/>
    <axis xyz="1 0 0"/>
    <limit effort="2.8" lower="-2.6179939" upper="2.6179939" velocity="5.6548668"/>
    <dynamics damping="0.0" friction="0.7"/>
    <safety_controller k_position="100" k_velocity="1.5" soft_lower_limit="-2.6179939" soft_upper_limit="2.6179939"/>
  </joint>
  <joint name="BL_tibia_joint" type="revolute">
    <parent link="thigh_BL"/>
    <child link="tibia_BL"/>
    <origin rpy="-1.5707 0 3.14159" xyz="0 -0.0645 -0.0145"/>
    <axis xyz="1 0 0"/>
    <limit effort="2.8" lower="-2.6179939" upper="2.6179939" velocity="5.6548668"/>
    <dynamics damping="0.0" friction="0.7"/>
    <safety_controller k_position="100" k_velocity="1.5" soft_lower_limit="-2.6179939" soft_upper_limit="2.6179939"/>
  </joint>
  <joint name="BL_foot_joint" type="fixed">
    <parent link="tibia_BL"/>
    <child link="foot_BL"/>
    <origin xyz="0 0.16 0.03"/>
    <safety_controller k_position="100" k_velocity="1.5" soft_lower_limit="0" soft_upper_limit="0"/>
  </joint>
  <transmission name="t_c1_BL">
    <type>transmission_interface/SimpleTransmission</type>
    <joint name="BL_coxa_joint">
      <hardwareInterface>hardware_interface/EffortJointInterface</hardwareInterface>
    </joint>
    <actuator name="m_c1_BL">
      <hardwareInterface>hardware_interface/EffortJointInterface</hardwareInterface>
      <mechanicalReduction>50</mechanicalReduction>
    </actuator>
  </transmission>
  <transmission name="t_thigh_BL">
    <type>transmission_interface/SimpleTransmission</type>
    <joint name="BL_femur_joint">
      <hardwareInterface>hardware_interface/EffortJointInterface</hardwareInterface>
    </joint>
    <actuator name="m_thigh_BL">
      <hardwareInterface>hardware_interface/EffortJointInterface</hardwareInterface>
      <mechanicalReduction>50</mechanicalReduction>
    </actuator>
  </transmission>
  <transmission name="t_tibia_BL">
    <type>transmission_interface/SimpleTransmission</type>
    <joint name="BL_tibia_joint">
      <hardwareInterface>hardware_interface/EffortJointInterface</hardwareInterface>
    </joint>
    <actuator name="m_tibia_BL">
      <hardwareInterface>hardware_interface/EffortJointInterface</hardwareInterface>
      <mechanicalReduction>50</mechanicalReduction>
    </actuator>
  </transmission>
  <gazebo reference="c1_BL">
    <material>Gazebo/Black</material>
    <mu1>0.8</mu1>
    <mu2>0.6</mu2>
    <kp>100</kp>
    <kd>10</kd>
    <gravity>True</gravity>
  </gazebo>
  <gazebo reference="c2_BL">
    <material>Gazebo/Black</material>
    <mu1>0.8</mu1>
    <mu2>0.6</mu2>
    <kp>100</kp>
    <kd>10</kd>
    <gravity>True</gravity>
  </gazebo>
  <gazebo reference="thigh_BL">
    <material>Gazebo/Black</material>
    <mu1>0.8</mu1>
    <mu2>0.6</mu2>
    <kp>100</kp>
    <kd>10</kd>
    <gravity>True</gravity>
  </gazebo>
  <gazebo reference="tibia_BL">
    <material>Gazebo/Black</material>
    <mu1>0.8</mu1>
    <mu2>0.6</mu2>
    <kp>1000</kp>
    <kd>10</kd>
    <gravity>True</gravity>
  </gazebo>
  <gazebo reference="foot_BL">
    <material>Gazebo/Blue</material>
    <mu1>0.8</mu1>
    <mu2>0.6</mu2>
    <kp>1000</kp>
    <kd>100</kd>
    <gravity>True</gravity>
    <sensor name="BL_foot_contact_sensor" type="contact">
      <always_on>true</always_on>
      <update_rate>1</update_rate>
      <contact>
        <collision>foot_BL_collision</collision>
      </contact>
      <plugin filename="libgazebo_ros_bumper.so" name="gripper_bumper">
        <bumperTopicName>BL_foot_contact_sensor_state</bumperTopicName>
        <frameName>BL_foot</frameName>
      </plugin>
    </sensor>
  </gazebo>
  <link name="c1_CL">
    <inertial>
      <origin rpy="0 0 0" xyz="0 -0.02633 0"/>
      <mass value="0.024357719"/>
      <inertia ixx="0.0051411124" ixy="-0.00057530255" ixz="-0.000024729049" iyy="0.0081915737" iyz="-0.000019223094" izz="0.0011379812"/>
    </inertial>
    <visual>
      <origin rpy="0 0 0" xyz="0 -0.0252 0"/>
      <geometry>
        <!--box size="0.045 0.022 0.0325" /-->
        <mesh filename="package://phantomx_description/meshes_mk3/connect.STL" scale="1 1 1"/>
      </geometry>
      <material name="Grey">
        <color rgba="0.20 0.20 0.20 1.0"/>
      </material>
    </visual>
    <collision>
      <origin rpy="0 0 0" xyz="0 -0.02633 0"/>
      <geometry>
        <mesh filename="package://phantomx_description/meshes_mk3/connect_coll.STL" scale="1 1 1"/>
      </geometry>
    </collision>
  </link>
  <link name="c2_CL">
    <inertial>
      <origin rpy="0 0 0" xyz="0 -0.02633 0"/>
      <mass value="0.024357719"/>
      <inertia ixx="0.0051411124" ixy="-0.00057530255" ixz="-0.000024729049" iyy="0.0081915737" iyz="-0.000019223094" izz="0.0011379812"/>
    </inertial>
    <visual>
      <origin rpy="0 0 0" xyz="0 -0.0252 0"/>
      <geometry>
        <!--box size="0.045 0.022 0.0325" /-->
        <mesh filename="package://phantomx_description/meshes_mk3/connect.STL" scale="1 1 1"/>
      </geometry>
      <material name="Grey">
        <color rgba="0.20 0.20 0.20 1.0"/>
      </material>
    </visual>
    <collision>
      <origin rpy="0 0 0" xyz="0 -0.02633 0"/>
      <geometry>
        <mesh filename="package://phantomx_description/meshes_mk3/connect_coll.STL" scale="1 1 1"/>
      </geometry>
    </collision>
  </link>
  <link name="thigh_CL">
    <inertial>
      <origin rpy="0 0 0" xyz="0 0 0"/>
      <mass value="0.024357719"/>
      <inertia ixx="0.0051411124" ixy="-0.00057530255" ixz="-0.000024729049" iyy="0.0081915737" iyz="-0.000019223094" izz="0.0011379812"/>
    </inertial>
    <visual>
      <origin rpy="0 0 0" xyz="0 0 0"/>
      <geometry>
        <!--box size="0.045 0.022 0.0325" /-->
        <mesh filename="package://phantomx_description/meshes_mk3/thigh_l.STL" scale="1 1 1"/>
      </geometry>
      <material name="Grey">
        <color rgba="0.20 0.20 0.20 1.0"/>
      </material>
    </visual>
    <collision>
      <origin rpy="0 0 0" xyz="0 0 0"/>
      <geometry>
        <mesh filename="package://phantomx_description/meshes_mk3/thigh_l_coll.STL" scale="1 1 1"/>
      </geometry>
    </collision>
  </link>
  <link name="tibia_CL">
    <inertial>
      <origin rpy="0 0 0" xyz="0 0 0"/>
      <mass value="0.024357719"/>
      <inertia ixx="0.0051411124" ixy="-0.00057530255" ixz="-0.000024729049" iyy="0.0081915737" iyz="-0.000019223094" izz="0.0011379812"/>
    </inertial>
    <visual>
      <origin rpy="0 0 0" xyz="0 0 0"/>
      <geometry>
        <!--box size="0.045 0.022 0.0325" /-->
        <mesh filename="package://phantomx_description/meshes_mk3/tibia_l.STL" scale="1 1 1"/>
      </geometry>
      <material name="Grey">
        <color rgba="0.20 0.20 0.20 1.0"/>
      </material>
    </visual>
    <collision>
      <origin rpy="0 0 0" xyz="0 0 0"/>
      <geometry>
        <mesh filename="package://phantomx_description/meshes_mk3/tibia_l_coll.STL" scale="1 1 1"/>
      </geometry>
    </collision>
  </link>
  <link name="foot_CL">
    <visual>
      <origin rpy="0 0 0" xyz="0 0 0"/>
      <geometry>
        <sphere radius="0.003"/>
      </geometry>
    </visual>
    <collision>
      <origin rpy="0 0 0" xyz="0 0 0"/>
      <geometry>
        <box size="0.01 0.01 0.01"/>
      </geometry>
    </collision>
  </link>
  <joint name="CL_coxa_joint" type="revolute">
    <parent link="MP_BODY"/>
    <child link="c1_CL"/>
    <origin rpy="0 4.7123 3.9269908169872414" xyz="-0.1248 0.06164  0.001116"/>
    <axis xyz="1 0 0"/>
    <limit effort="2.8" lower="-2.6179939" upper="2.6179939" velocity="5.6548668"/>
    <dynamics damping="0.0" friction="0.7"/>
    <safety_controller k_position="100" k_velocity="1.5" soft_lower_limit="-2.6179939" soft_upper_limit="2.6179939"/>
  </joint>
  <joint name="j_c2_CL" type="fixed">
    <parent link="c1_CL"/>
    <child link="c2_CL"/>
    <origin rpy="0 1.5704 3.14159" xyz="0 -0.054 0"/>
    <safety_controller k_position="100" k_velocity="1.5" soft_lower_limit="0" soft_upper_limit="0"/>
  </joint>
  <joint name="CL_femur_joint" type="revolute">
    <parent link="c2_CL"/>
    <child link="thigh_CL"/>
    <origin rpy=" 0 3.14159 3.14159" xyz="0 0 0"/>
    <axis xyz="1 0 0"/>
    <limit effort="2.8" lower="-2.6179939" upper="2.6179939" velocity="5.6548668"/>
    <dynamics damping="0.0" friction="0.7"/>
    <safety_controller k_position="100" k_velocity="1.5" soft_lower_limit="-2.6179939" soft_upper_limit="2.6179939"/>
  </joint>
  <joint name="CL_tibia_joint" type="revolute">
    <parent link="thigh_CL"/>
    <child link="tibia_CL"/>
    <origin rpy="-1.5707 0 3.14159" xyz="0 -0.0645 -0.0145"/>
    <axis xyz="1 0 0"/>
    <limit effort="2.8" lower="-2.6179939" upper="2.6179939" velocity="5.6548668"/>
    <dynamics damping="0.0" friction="0.7"/>
    <safety_controller k_position="100" k_velocity="1.5" soft_lower_limit="-2.6179939" soft_upper_limit="2.6179939"/>
  </joint>
  <joint name="CL_foot_joint" type="fixed">
    <parent link="tibia_CL"/>
    <child link="foot_CL"/>
    <origin xyz="0 0.16 0.03"/>
    <safety_controller k_position="100" k_velocity="1.5" soft_lower_limit="0" soft_upper_limit="0"/>
  </joint>
  <transmission name="t_c1_CL">
    <type>transmission_interface/SimpleTransmission</type>
    <joint name="CL_coxa_joint">
      <hardwareInterface>hardware_interface/EffortJointInterface</hardwareInterface>
    </joint>
    <actuator name="m_c1_CL">
      <hardwareInterface>hardware_interface/EffortJointInterface</hardwareInterface>
      <mechanicalReduction>50</mechanicalReduction>
    </actuator>
  </transmission>
  <transmission name="t_thigh_CL">
    <type>transmission_interface/SimpleTransmission</type>
    <joint name="CL_femur_joint">
      <hardwareInterface>hardware_interface/EffortJointInterface</hardwareInterface>
    </joint>
    <actuator name="m_thigh_CL">
      <hardwareInterface>hardware_interface/EffortJointInterface</hardwareInterface>
      <mechanicalReduction>50</mechanicalReduction>
    </actuator>
  </transmission>
  <transmission name="t_tibia_CL">
    <type>transmission_interface/SimpleTransmission</type>
    <joint name="CL_tibia_joint">
      <hardwareInterface>hardware_interface/EffortJointInterface</hardwareInterface>
    </joint>
    <actuator name="m_tibia_CL">
      <hardwareInterface>hardware_interface/EffortJointInterface</hardwareInterface>
      <mechanicalReduction>50</mechanicalReduction>
    </actuator>
  </transmission>
  <gazebo reference="c1_CL">
    <material>Gazebo/Black</material>
    <mu1>0.8</mu1>
    <mu2>0.6</mu2>
    <kp>100</kp>
    <kd>10</kd>
    <gravity>True</gravity>
  </gazebo>
  <gazebo reference="c2_CL">
    <material>Gazebo/Black</material>
    <mu1>0.8</mu1>
    <mu2>0.6</mu2>
    <kp>100</kp>
    <kd>10</kd>
    <gravity>True</gravity>
  </gazebo>
  <gazebo reference="thigh_CL">
    <material>Gazebo/Black</material>
    <mu1>0.8</mu1>
    <mu2>0.6</mu2>
    <kp>100</kp>
    <kd>10</kd>
    <gravity>True</gravity>
  </gazebo>
  <gazebo reference="tibia_CL">
    <material>Gazebo/Black</material>
    <mu1>0.8</mu1>
    <mu2>0.6</mu2>
    <kp>1000</kp>
    <kd>10</kd>
    <gravity>True</gravity>
  </gazebo>
  <gazebo reference="foot_CL">
    <material>Gazebo/Blue</material>
    <mu1>0.8</mu1>
    <mu2>0.6</mu2>
    <kp>1000</kp>
    <kd>100</kd>
    <gravity>True</gravity>
    <sensor name="CL_foot_contact_sensor" type="contact">
      <always_on>true</always_on>
      <update_rate>1</update_rate>
      <contact>
        <collision>foot_CL_collision</collision>
      </contact>
      <plugin filename="libgazebo_ros_bumper.so" name="gripper_bumper">
        <bumperTopicName>CL_foot_contact_sensor_state</bumperTopicName>
        <frameName>CL_foot</frameName>
      </plugin>
    </sensor>
  </gazebo>
  <gazebo>
    <plugin filename="libgazebo_ros_control.so" name="gazebo_ros_control">
      <!--robotNamespace>/phantomx</robotNamespace-->
    </plugin>
  </gazebo>
</robot>

