<?xml version="1.0" ?>
<!-- =================================================================================== -->
<!-- |    This document was autogenerated by xacro from phantomx.xacro                 | -->
<!-- |    EDITING THIS FILE BY HAND IS NOT RECOMMENDED                                 | -->
<!-- =================================================================================== -->
<robot name="phantomx" xmlns:xacro="http://ros.org/wiki/xacro">
  <!-- ros_control plugin -->
  <gazebo>
    <plugin filename="libgazebo_ros_control.so" name="gazebo_ros_control">
      <!--robotNamespace>/phantomx</robotNamespace-->
      <robotSimType>gazebo_ros_control/DefaultRobotHWSim</robotSimType>
    </plugin>
  </gazebo>
  <!-- Base link -->
  <gazebo reference="base_link">
    <material>Gazebo/Black</material>
  </gazebo>
  <material name="black">
    <color rgba="0.13 0.13 0.13 1.0"/>
  </material>
  <material name="blue">
    <color rgba="0.0 0.0 0.8 1.0"/>
  </material>
  <material name="green">
    <color rgba="0.0 0.8 0.0 1.0"/>
  </material>
  <material name="grey">
    <color rgba="0.2 0.2 0.2 1.0"/>
  </material>
  <material name="orange">
    <color rgba="1.0 0.423529411765 0.0392156862745 1.0"/>
  </material>
  <material name="brown">
    <color rgba="0.870588235294 0.811764705882 0.764705882353 1.0"/>
  </material>
  <material name="red">
    <color rgba="0.8 0.0 0.0 1.0"/>
  </material>
  <material name="white">
    <color rgba="1.0 1.0 1.0 1.0"/>
  </material>
  <!-- Add a kinect sensor : first the visual/collision/inertial box -->
  <link name="kinect_link">
    <collision>
      <origin rpy="0 0 0" xyz="0 0 0"/>
      <geometry>
        <!-- coarse model; a simple box -->
        <box size="0.05 0.2 0.05"/>
      </geometry>
    </collision>
    <visual>
      <origin rpy="0 0 0" xyz="0 0 0"/>
      <geometry>
        <box size="0.05 0.2 0.05"/>
      </geometry>
      <material name="kinect_gray">
        <color rgba="0.2 0.2 0.2 1.0"/>
      </material>
    </visual>
    <inertial>
      <mass value="0.1"/>
      <origin rpy="0 0 0" xyz="0 0 0"/>
      <inertia ixx="0.001" ixy="0" ixz="0" iyy="0.001" iyz="0" izz="0.001"/>
    </inertial>
  </link>
  <!-- Position and orientation of the kinect sensor -->
  <joint name="kinect_joint" type="fixed">
    <axis xyz="0 1 0"/>
    <origin rpy="0.0 0.6 0" xyz="0.1 0.0 0.1"/>
    <parent link="base_link"/>
    <child link="kinect_link"/>
  </joint>
  <joint name="camera_optical_joint" type="fixed">
    <!--Don't change these values, otherwise the gazebo camera image won't be aligned properly with the frame it is supposedly originating from-->
    <origin rpy="-1.57079632679 0 -1.57079632679" xyz="0 0 0"/>
    <parent link="kinect_link"/>
    <child link="camera_link_optical"/>
  </joint>
  <link name="camera_link_optical">
	</link>
  <!--Add kinect sensor emulation-->
  <gazebo reference="kinect_link">
    <sensor name="camera_1" type="depth">
      <always_on>1</always_on>
      <visualize>true</visualize>
      <camera>
        <horizontal_fov>1.047</horizontal_fov>
        <image>
          <width>640</width>
          <height>480</height>
          <format>R8G8B8</format>
        </image>
        <depth_camera>
				</depth_camera>
        <clip>
          <near>0.1</near>
          <far>100</far>
        </clip>
      </camera>
      <plugin filename="libgazebo_ros_openni_kinect.so" name="camera_controller">
        <alwaysOn>true</alwaysOn>
        <updateRate>10.0</updateRate>
        <cameraName>kinect</cameraName>
        <frameName>camera_link_optical</frameName>
        <imageTopicName>rgb/image_raw</imageTopicName>
        <depthImageTopicName>depth/image_raw</depthImageTopicName>
        <pointCloudTopicName>depth/points</pointCloudTopicName>
        <cameraInfoTopicName>rgb/camera_info</cameraInfoTopicName>
        <depthImageCameraInfoTopicName>depht/camera_info</depthImageCameraInfoTopicName>
        <pointCloudCutoff>0.4</pointCloudCutoff>
        <hackBaseline>0.07</hackBaseline>
        <distortionK1>0.0</distortionK1>
        <distortionK2>0.0</distortionK2>
        <distortionK3>0.0</distortionK3>
        <distortionT1>0.0</distortionT1>
        <distortionT2>0.0</distortionT2>
        <CxPrime>0.0</CxPrime>
        <Cx>0.0</Cx>
        <Cy>0.0</Cy>
        <focalLength>0.0</focalLength>
      </plugin>
    </sensor>
  </gazebo>
  <!-- Root link -->
  <link name="root_link"/>
  <!-- Base link -->
  <link name="base_link">
    <visual>
      <geometry>
        <mesh filename="package://phantomx_description/meshes/base_link.stl"/>
      </geometry>
      <origin rpy="0 0 0" xyz="0 0 0"/>
      <material name="black"/>
    </visual>
    <collision>
      <geometry>
        <mesh filename="package://phantomx_description/meshes/base_link_simple.stl"/>
      </geometry>
      <origin rpy="0 0 0" xyz="0 0 0"/>
    </collision>
    <inertial>
      <origin xyz="0 0 0"/>
      <mass value="0.97559947"/>
      <inertia ixx="3.1081800" ixy="-0.25460189" ixz="2.0318174" iyy="6.3787776" iyz="0.16417863" izz="5.3316425"/>
    </inertial>
  </link>
  <joint name="root_joint" type="fixed">
    <parent link="root_link"/>
    <child link="base_link"/>
    <origin xyz="0 0 0"/>
  </joint>
  <link name="AL_coxa_link">
    <visual>
      <geometry>
        <mesh filename="package://phantomx_description/meshes/coxa_link.STL"/>
      </geometry>
      <origin rpy="0 0 0" xyz="0 0 0"/>
      <material name="black"/>
    </visual>
    <collision>
      <geometry>
        <mesh filename="package://phantomx_description/meshes/coxa_link_simple.STL"/>
      </geometry>
      <origin rpy="0 0 0" xyz="0 0 0"/>
    </collision>
    <inertial>
      <origin xyz="0.024001547 0 0"/>
      <mass value="0.01096414"/>
      <inertia ixx="0.01" ixy="0.0" ixz="0.0" iyy="0.01" iyz="0.0" izz="0.01"/>
    </inertial>
  </link>
  <link name="AL_femur_link">
    <visual>
      <geometry>
        <mesh filename="package://phantomx_description/meshes/femur_link.STL"/>
      </geometry>
      <origin rpy="0 0 0" xyz="0 0 0"/>
      <material name="black"/>
    </visual>
    <collision>
      <geometry>
        <mesh filename="package://phantomx_description/meshes/femur_link_simple.STL"/>
      </geometry>
      <origin rpy="0 0 0" xyz="0 0 0"/>
    </collision>
    <inertial>
      <origin xyz="0.04208275 0.00000123 -0.00098111"/>
      <mass value="0.12147677"/>
      <inertia ixx="0.01" ixy="0.0" ixz="0" iyy="0.01" iyz="0.0" izz="0.01"/>
    </inertial>
  </link>
  <link name="AL_tibia_link">
    <visual>
      <geometry>
        <mesh filename="package://phantomx_description/meshes/tibia_link.STL"/>
      </geometry>
      <origin rpy="0 0 0" xyz="0 0 0"/>
      <material name="black"/>
    </visual>
    <collision>
      <geometry>
        <mesh filename="package://phantomx_description/meshes/tibia_link_simple.STL"/>
      </geometry>
      <origin rpy="0 0 0" xyz="0 0 0"/>
    </collision>
    <inertial>
      <origin xyz="0.05151483 0 0"/>
      <mass value="0.03741374"/>
      <inertia ixx="0.01" ixy="0.0" ixz="0.0" iyy="0.01" iyz="0.0" izz="0.01"/>
    </inertial>
  </link>
  <link name="AL_foot_link"/>
  <joint name="AL_coxa_joint" type="revolute">
    <parent link="base_link"/>
    <child link="AL_coxa_link"/>
    <limit effort="1000.0" lower="-3.14" upper="3.14" velocity="1.0"/>
    <axis xyz="0 0 1"/>
    <origin rpy="0 0 0.7853981635" xyz="0.12 0.06 0"/>
    <dynamics damping="1.5" friction="1.5"/>
  </joint>
  <joint name="AL_femur_joint" type="revolute">
    <parent link="AL_coxa_link"/>
    <child link="AL_femur_link"/>
    <limit effort="1000.0" lower="-1.5707" upper="1.5707" velocity="1.0"/>
    <axis xyz="0 0 -1"/>
    <origin rpy="1.5707 0 0" xyz="0.048 0 0"/>
    <dynamics damping="1.5" friction="1.5"/>
  </joint>
  <joint name="AL_tibia_joint" type="revolute">
    <parent link="AL_femur_link"/>
    <child link="AL_tibia_link"/>
    <limit effort="1000.0" lower="-2.3562" upper="2.3562" velocity="1.0"/>
    <axis xyz="0 0 1"/>
    <origin rpy="0 0 -1.570796327" xyz="0.083 0 0"/>
    <dynamics damping="1.5" friction="1.5"/>
  </joint>
  <joint name="AL_foot_joint" type="fixed">
    <parent link="AL_tibia_link"/>
    <child link="AL_foot_link"/>
    <limit effort="1000.0" lower="-2.3562" upper="2.3562" velocity="1.0"/>
    <axis xyz="1 0 0"/>
    <origin rpy="0 0 0" xyz="0.143 0 0"/>
  </joint>
  <transmission name="tran_AL_coxa">
    <type>transmission_interface/SimpleTransmission</type>
    <joint name="AL_coxa_joint">
      <hardwareInterface>hardware_interface/EffortJointInterface</hardwareInterface>
    </joint>
    <actuator name="motor_AL_coxa">
      <hardwareInterface>hardware_interface/EffortJointInterface</hardwareInterface>
      <mechanicalReduction>50</mechanicalReduction>
    </actuator>
  </transmission>
  <transmission name="tran_AL_femur">
    <type>transmission_interface/SimpleTransmission</type>
    <joint name="AL_femur_joint">
      <hardwareInterface>hardware_interface/EffortJointInterface</hardwareInterface>
    </joint>
    <actuator name="motor_AL_femur">
      <hardwareInterface>hardware_interface/EffortJointInterface</hardwareInterface>
      <mechanicalReduction>50</mechanicalReduction>
    </actuator>
  </transmission>
  <transmission name="tran_AL_tibia">
    <type>transmission_interface/SimpleTransmission</type>
    <joint name="AL_tibia_joint">
      <hardwareInterface>hardware_interface/EffortJointInterface</hardwareInterface>
    </joint>
    <actuator name="motor_AL_tibia">
      <hardwareInterface>hardware_interface/EffortJointInterface</hardwareInterface>
      <mechanicalReduction>50</mechanicalReduction>
    </actuator>
  </transmission>
  <gazebo reference="AL_coxa_link">
    <material>Gazebo/Black</material>
    <mu1>0.8</mu1>
    <mu2>0.6</mu2>
    <kp>100</kp>
    <kd>10</kd>
    <gravity>True</gravity>
  </gazebo>
  <gazebo reference="AL_femur_link">
    <material>Gazebo/Black</material>
    <mu1>0.8</mu1>
    <mu2>0.6</mu2>
    <kp>100</kp>
    <kd>10</kd>
    <gravity>True</gravity>
  </gazebo>
  <gazebo reference="AL_tibia_link">
    <material>Gazebo/Black</material>
    <mu1>0.8</mu1>
    <mu2>0.6</mu2>
    <kp>1000</kp>
    <kd>100</kd>
    <gravity>True</gravity>
  </gazebo>
  <gazebo reference="AL_tibia_link">
    <sensor name="AL_foot_contact_sensor" type="contact">
      <always_on>true</always_on>
      <update_rate>30</update_rate>
      <contact>
        <collision>AL_collision</collision>
      </contact>
      <plugin filename="libgazebo_ros_bumper.so" name="gripper_bumper">
        <bumperTopicName>AL_foot_contact_sensor_state</bumperTopicName>
        <frameName>AL_foot</frameName>
      </plugin>
    </sensor>
  </gazebo>
  <link name="AR_coxa_link">
    <visual>
      <geometry>
        <mesh filename="package://phantomx_description/meshes/coxa_link.STL"/>
      </geometry>
      <origin rpy="0 0 0" xyz="0 0 0"/>
      <material name="black"/>
    </visual>
    <collision>
      <geometry>
        <mesh filename="package://phantomx_description/meshes/coxa_link_simple.STL"/>
      </geometry>
      <origin rpy="0 0 0" xyz="0 0 0"/>
    </collision>
    <inertial>
      <origin xyz="0.024001547 0 0"/>
      <mass value="0.01096414"/>
      <inertia ixx="0.01" ixy="0.0" ixz="0.0" iyy="0.01" iyz="0.0" izz="0.01"/>
    </inertial>
  </link>
  <link name="AR_femur_link">
    <visual>
      <geometry>
        <mesh filename="package://phantomx_description/meshes/femur_link.STL"/>
      </geometry>
      <origin rpy="0 0 0" xyz="0 0 0"/>
      <material name="black"/>
    </visual>
    <collision>
      <geometry>
        <mesh filename="package://phantomx_description/meshes/femur_link_simple.STL"/>
      </geometry>
      <origin rpy="0 0 0" xyz="0 0 0"/>
    </collision>
    <inertial>
      <origin xyz="0.04208275 0.00000123 -0.00098111"/>
      <mass value="0.12147677"/>
      <inertia ixx="0.01" ixy="0.0" ixz="0" iyy="0.01" iyz="0.0" izz="0.01"/>
    </inertial>
  </link>
  <link name="AR_tibia_link">
    <visual>
      <geometry>
        <mesh filename="package://phantomx_description/meshes/tibia_link.STL"/>
      </geometry>
      <origin rpy="0 0 0" xyz="0 0 0"/>
      <material name="black"/>
    </visual>
    <collision>
      <geometry>
        <mesh filename="package://phantomx_description/meshes/tibia_link_simple.STL"/>
      </geometry>
      <origin rpy="0 0 0" xyz="0 0 0"/>
    </collision>
    <inertial>
      <origin xyz="0.05151483 0 0"/>
      <mass value="0.03741374"/>
      <inertia ixx="0.01" ixy="0.0" ixz="0.0" iyy="0.01" iyz="0.0" izz="0.01"/>
    </inertial>
  </link>
  <link name="AR_foot_link"/>
  <joint name="AR_coxa_joint" type="revolute">
    <parent link="base_link"/>
    <child link="AR_coxa_link"/>
    <limit effort="1000.0" lower="-3.14" upper="3.14" velocity="1.0"/>
    <axis xyz="0 0 1"/>
    <origin rpy="0 0 -0.7853981635" xyz="0.12 -0.06 0"/>
    <dynamics damping="1.5" friction="1.5"/>
  </joint>
  <joint name="AR_femur_joint" type="revolute">
    <parent link="AR_coxa_link"/>
    <child link="AR_femur_link"/>
    <limit effort="1000.0" lower="-1.5707" upper="1.5707" velocity="1.0"/>
    <axis xyz="0 0 1"/>
    <origin rpy="1.5707 0 0" xyz="0.048 0 0"/>
    <dynamics damping="1.5" friction="1.5"/>
  </joint>
  <joint name="AR_tibia_joint" type="revolute">
    <parent link="AR_femur_link"/>
    <child link="AR_tibia_link"/>
    <limit effort="1000.0" lower="-2.3562" upper="2.3562" velocity="1.0"/>
    <axis xyz="0 0 -1"/>
    <origin rpy="0 0 -1.570796327" xyz="0.083 0 0"/>
    <dynamics damping="1.5" friction="1.5"/>
  </joint>
  <joint name="AR_foot_joint" type="fixed">
    <parent link="AR_tibia_link"/>
    <child link="AR_foot_link"/>
    <limit effort="1000.0" lower="-2.3562" upper="2.3562" velocity="1.0"/>
    <axis xyz="1 0 0"/>
    <origin rpy="0 0 0" xyz="0.143 0 0"/>
  </joint>
  <transmission name="tran_AR_coxa">
    <type>transmission_interface/SimpleTransmission</type>
    <joint name="AR_coxa_joint">
      <hardwareInterface>hardware_interface/EffortJointInterface</hardwareInterface>
    </joint>
    <actuator name="motor_AR_coxa">
      <hardwareInterface>hardware_interface/EffortJointInterface</hardwareInterface>
      <mechanicalReduction>50</mechanicalReduction>
    </actuator>
  </transmission>
  <transmission name="tran_AR_femur">
    <type>transmission_interface/SimpleTransmission</type>
    <joint name="AR_femur_joint">
      <hardwareInterface>hardware_interface/EffortJointInterface</hardwareInterface>
    </joint>
    <actuator name="motor_AR_femur">
      <hardwareInterface>hardware_interface/EffortJointInterface</hardwareInterface>
      <mechanicalReduction>50</mechanicalReduction>
    </actuator>
  </transmission>
  <transmission name="tran_AR_tibia">
    <type>transmission_interface/SimpleTransmission</type>
    <joint name="AR_tibia_joint">
      <hardwareInterface>hardware_interface/EffortJointInterface</hardwareInterface>
    </joint>
    <actuator name="motor_AR_tibia">
      <hardwareInterface>hardware_interface/EffortJointInterface</hardwareInterface>
      <mechanicalReduction>50</mechanicalReduction>
    </actuator>
  </transmission>
  <gazebo reference="AR_coxa_link">
    <material>Gazebo/Black</material>
    <mu1>0.8</mu1>
    <mu2>0.6</mu2>
    <kp>100</kp>
    <kd>10</kd>
    <gravity>True</gravity>
  </gazebo>
  <gazebo reference="AR_femur_link">
    <material>Gazebo/Black</material>
    <mu1>0.8</mu1>
    <mu2>0.6</mu2>
    <kp>100</kp>
    <kd>10</kd>
    <gravity>True</gravity>
  </gazebo>
  <gazebo reference="AR_tibia_link">
    <material>Gazebo/Black</material>
    <mu1>0.8</mu1>
    <mu2>0.6</mu2>
    <kp>1000</kp>
    <kd>100</kd>
    <gravity>True</gravity>
  </gazebo>
  <gazebo reference="AR_tibia_link">
    <sensor name="AR_foot_contact_sensor" type="contact">
      <always_on>true</always_on>
      <update_rate>30</update_rate>
      <contact>
        <collision>AR_collision</collision>
      </contact>
      <plugin filename="libgazebo_ros_bumper.so" name="gripper_bumper">
        <bumperTopicName>AR_foot_contact_sensor_state</bumperTopicName>
        <frameName>AR_foot</frameName>
      </plugin>
    </sensor>
  </gazebo>
  <link name="BL_coxa_link">
    <visual>
      <geometry>
        <mesh filename="package://phantomx_description/meshes/coxa_link.STL"/>
      </geometry>
      <origin rpy="0 0 0" xyz="0 0 0"/>
      <material name="black"/>
    </visual>
    <collision>
      <geometry>
        <mesh filename="package://phantomx_description/meshes/coxa_link_simple.STL"/>
      </geometry>
      <origin rpy="0 0 0" xyz="0 0 0"/>
    </collision>
    <inertial>
      <origin xyz="0.024001547 0 0"/>
      <mass value="0.01096414"/>
      <inertia ixx="0.01" ixy="0.0" ixz="0.0" iyy="0.01" iyz="0.0" izz="0.01"/>
    </inertial>
  </link>
  <link name="BL_femur_link">
    <visual>
      <geometry>
        <mesh filename="package://phantomx_description/meshes/femur_link.STL"/>
      </geometry>
      <origin rpy="0 0 0" xyz="0 0 0"/>
      <material name="black"/>
    </visual>
    <collision>
      <geometry>
        <mesh filename="package://phantomx_description/meshes/femur_link_simple.STL"/>
      </geometry>
      <origin rpy="0 0 0" xyz="0 0 0"/>
    </collision>
    <inertial>
      <origin xyz="0.04208275 0.00000123 -0.00098111"/>
      <mass value="0.12147677"/>
      <inertia ixx="0.01" ixy="0.0" ixz="0" iyy="0.01" iyz="0.0" izz="0.01"/>
    </inertial>
  </link>
  <link name="BL_tibia_link">
    <visual>
      <geometry>
        <mesh filename="package://phantomx_description/meshes/tibia_link.STL"/>
      </geometry>
      <origin rpy="0 0 0" xyz="0 0 0"/>
      <material name="black"/>
    </visual>
    <collision>
      <geometry>
        <mesh filename="package://phantomx_description/meshes/tibia_link_simple.STL"/>
      </geometry>
      <origin rpy="0 0 0" xyz="0 0 0"/>
    </collision>
    <inertial>
      <origin xyz="0.05151483 0 0"/>
      <mass value="0.03741374"/>
      <inertia ixx="0.01" ixy="0.0" ixz="0.0" iyy="0.01" iyz="0.0" izz="0.01"/>
    </inertial>
  </link>
  <link name="BL_foot_link"/>
  <joint name="BL_coxa_joint" type="revolute">
    <parent link="base_link"/>
    <child link="BL_coxa_link"/>
    <limit effort="1000.0" lower="-3.14" upper="3.14" velocity="1.0"/>
    <axis xyz="0 0 1"/>
    <origin rpy="0 0 1.570796327" xyz="0 0.1 0"/>
    <dynamics damping="1.5" friction="1.5"/>
  </joint>
  <joint name="BL_femur_joint" type="revolute">
    <parent link="BL_coxa_link"/>
    <child link="BL_femur_link"/>
    <limit effort="1000.0" lower="-1.5707" upper="1.5707" velocity="1.0"/>
    <axis xyz="0 0 -1"/>
    <origin rpy="1.5707 0 0" xyz="0.048 0 0"/>
    <dynamics damping="1.5" friction="1.5"/>
  </joint>
  <joint name="BL_tibia_joint" type="revolute">
    <parent link="BL_femur_link"/>
    <child link="BL_tibia_link"/>
    <limit effort="1000.0" lower="-2.3562" upper="2.3562" velocity="1.0"/>
    <axis xyz="0 0 1"/>
    <origin rpy="0 0 -1.570796327" xyz="0.083 0 0"/>
    <dynamics damping="1.5" friction="1.5"/>
  </joint>
  <joint name="BL_foot_joint" type="fixed">
    <parent link="BL_tibia_link"/>
    <child link="BL_foot_link"/>
    <limit effort="1000.0" lower="-2.3562" upper="2.3562" velocity="1.0"/>
    <axis xyz="1 0 0"/>
    <origin rpy="0 0 0" xyz="0.143 0 0"/>
  </joint>
  <transmission name="tran_BL_coxa">
    <type>transmission_interface/SimpleTransmission</type>
    <joint name="BL_coxa_joint">
      <hardwareInterface>hardware_interface/EffortJointInterface</hardwareInterface>
    </joint>
    <actuator name="motor_BL_coxa">
      <hardwareInterface>hardware_interface/EffortJointInterface</hardwareInterface>
      <mechanicalReduction>50</mechanicalReduction>
    </actuator>
  </transmission>
  <transmission name="tran_BL_femur">
    <type>transmission_interface/SimpleTransmission</type>
    <joint name="BL_femur_joint">
      <hardwareInterface>hardware_interface/EffortJointInterface</hardwareInterface>
    </joint>
    <actuator name="motor_BL_femur">
      <hardwareInterface>hardware_interface/EffortJointInterface</hardwareInterface>
      <mechanicalReduction>50</mechanicalReduction>
    </actuator>
  </transmission>
  <transmission name="tran_BL_tibia">
    <type>transmission_interface/SimpleTransmission</type>
    <joint name="BL_tibia_joint">
      <hardwareInterface>hardware_interface/EffortJointInterface</hardwareInterface>
    </joint>
    <actuator name="motor_BL_tibia">
      <hardwareInterface>hardware_interface/EffortJointInterface</hardwareInterface>
      <mechanicalReduction>50</mechanicalReduction>
    </actuator>
  </transmission>
  <gazebo reference="BL_coxa_link">
    <material>Gazebo/Black</material>
    <mu1>0.8</mu1>
    <mu2>0.6</mu2>
    <kp>100</kp>
    <kd>10</kd>
    <gravity>True</gravity>
  </gazebo>
  <gazebo reference="BL_femur_link">
    <material>Gazebo/Black</material>
    <mu1>0.8</mu1>
    <mu2>0.6</mu2>
    <kp>100</kp>
    <kd>10</kd>
    <gravity>True</gravity>
  </gazebo>
  <gazebo reference="BL_tibia_link">
    <material>Gazebo/Black</material>
    <mu1>0.8</mu1>
    <mu2>0.6</mu2>
    <kp>1000</kp>
    <kd>100</kd>
    <gravity>True</gravity>
  </gazebo>
  <gazebo reference="BL_tibia_link">
    <sensor name="BL_foot_contact_sensor" type="contact">
      <always_on>true</always_on>
      <update_rate>30</update_rate>
      <contact>
        <collision>BL_collision</collision>
      </contact>
      <plugin filename="libgazebo_ros_bumper.so" name="gripper_bumper">
        <bumperTopicName>BL_foot_contact_sensor_state</bumperTopicName>
        <frameName>BL_foot</frameName>
      </plugin>
    </sensor>
  </gazebo>
  <link name="BR_coxa_link">
    <visual>
      <geometry>
        <mesh filename="package://phantomx_description/meshes/coxa_link.STL"/>
      </geometry>
      <origin rpy="0 0 0" xyz="0 0 0"/>
      <material name="black"/>
    </visual>
    <collision>
      <geometry>
        <mesh filename="package://phantomx_description/meshes/coxa_link_simple.STL"/>
      </geometry>
      <origin rpy="0 0 0" xyz="0 0 0"/>
    </collision>
    <inertial>
      <origin xyz="0.024001547 0 0"/>
      <mass value="0.01096414"/>
      <inertia ixx="0.01" ixy="0.0" ixz="0.0" iyy="0.01" iyz="0.0" izz="0.01"/>
    </inertial>
  </link>
  <link name="BR_femur_link">
    <visual>
      <geometry>
        <mesh filename="package://phantomx_description/meshes/femur_link.STL"/>
      </geometry>
      <origin rpy="0 0 0" xyz="0 0 0"/>
      <material name="black"/>
    </visual>
    <collision>
      <geometry>
        <mesh filename="package://phantomx_description/meshes/femur_link_simple.STL"/>
      </geometry>
      <origin rpy="0 0 0" xyz="0 0 0"/>
    </collision>
    <inertial>
      <origin xyz="0.04208275 0.00000123 -0.00098111"/>
      <mass value="0.12147677"/>
      <inertia ixx="0.01" ixy="0.0" ixz="0" iyy="0.01" iyz="0.0" izz="0.01"/>
    </inertial>
  </link>
  <link name="BR_tibia_link">
    <visual>
      <geometry>
        <mesh filename="package://phantomx_description/meshes/tibia_link.STL"/>
      </geometry>
      <origin rpy="0 0 0" xyz="0 0 0"/>
      <material name="black"/>
    </visual>
    <collision>
      <geometry>
        <mesh filename="package://phantomx_description/meshes/tibia_link_simple.STL"/>
      </geometry>
      <origin rpy="0 0 0" xyz="0 0 0"/>
    </collision>
    <inertial>
      <origin xyz="0.05151483 0 0"/>
      <mass value="0.03741374"/>
      <inertia ixx="0.01" ixy="0.0" ixz="0.0" iyy="0.01" iyz="0.0" izz="0.01"/>
    </inertial>
  </link>
  <link name="BR_foot_link"/>
  <joint name="BR_coxa_joint" type="revolute">
    <parent link="base_link"/>
    <child link="BR_coxa_link"/>
    <limit effort="1000.0" lower="-3.14" upper="3.14" velocity="1.0"/>
    <axis xyz="0 0 1"/>
    <origin rpy="0 0 -1.570796327" xyz="0 -0.1 0"/>
    <dynamics damping="1.5" friction="1.5"/>
  </joint>
  <joint name="BR_femur_joint" type="revolute">
    <parent link="BR_coxa_link"/>
    <child link="BR_femur_link"/>
    <limit effort="1000.0" lower="-1.5707" upper="1.5707" velocity="1.0"/>
    <axis xyz="0 0 1"/>
    <origin rpy="1.5707 0 0" xyz="0.048 0 0"/>
    <dynamics damping="1.5" friction="1.5"/>
  </joint>
  <joint name="BR_tibia_joint" type="revolute">
    <parent link="BR_femur_link"/>
    <child link="BR_tibia_link"/>
    <limit effort="1000.0" lower="-2.3562" upper="2.3562" velocity="1.0"/>
    <axis xyz="0 0 -1"/>
    <origin rpy="0 0 -1.570796327" xyz="0.083 0 0"/>
    <dynamics damping="1.5" friction="1.5"/>
  </joint>
  <joint name="BR_foot_joint" type="fixed">
    <parent link="BR_tibia_link"/>
    <child link="BR_foot_link"/>
    <limit effort="1000.0" lower="-2.3562" upper="2.3562" velocity="1.0"/>
    <axis xyz="1 0 0"/>
    <origin rpy="0 0 0" xyz="0.143 0 0"/>
  </joint>
  <transmission name="tran_BR_coxa">
    <type>transmission_interface/SimpleTransmission</type>
    <joint name="BR_coxa_joint">
      <hardwareInterface>hardware_interface/EffortJointInterface</hardwareInterface>
    </joint>
    <actuator name="motor_BR_coxa">
      <hardwareInterface>hardware_interface/EffortJointInterface</hardwareInterface>
      <mechanicalReduction>50</mechanicalReduction>
    </actuator>
  </transmission>
  <transmission name="tran_BR_femur">
    <type>transmission_interface/SimpleTransmission</type>
    <joint name="BR_femur_joint">
      <hardwareInterface>hardware_interface/EffortJointInterface</hardwareInterface>
    </joint>
    <actuator name="motor_BR_femur">
      <hardwareInterface>hardware_interface/EffortJointInterface</hardwareInterface>
      <mechanicalReduction>50</mechanicalReduction>
    </actuator>
  </transmission>
  <transmission name="tran_BR_tibia">
    <type>transmission_interface/SimpleTransmission</type>
    <joint name="BR_tibia_joint">
      <hardwareInterface>hardware_interface/EffortJointInterface</hardwareInterface>
    </joint>
    <actuator name="motor_BR_tibia">
      <hardwareInterface>hardware_interface/EffortJointInterface</hardwareInterface>
      <mechanicalReduction>50</mechanicalReduction>
    </actuator>
  </transmission>
  <gazebo reference="BR_coxa_link">
    <material>Gazebo/Black</material>
    <mu1>0.8</mu1>
    <mu2>0.6</mu2>
    <kp>100</kp>
    <kd>10</kd>
    <gravity>True</gravity>
  </gazebo>
  <gazebo reference="BR_femur_link">
    <material>Gazebo/Black</material>
    <mu1>0.8</mu1>
    <mu2>0.6</mu2>
    <kp>100</kp>
    <kd>10</kd>
    <gravity>True</gravity>
  </gazebo>
  <gazebo reference="BR_tibia_link">
    <material>Gazebo/Black</material>
    <mu1>0.8</mu1>
    <mu2>0.6</mu2>
    <kp>1000</kp>
    <kd>100</kd>
    <gravity>True</gravity>
  </gazebo>
  <gazebo reference="BR_tibia_link">
    <sensor name="BR_foot_contact_sensor" type="contact">
      <always_on>true</always_on>
      <update_rate>30</update_rate>
      <contact>
        <collision>BR_collision</collision>
      </contact>
      <plugin filename="libgazebo_ros_bumper.so" name="gripper_bumper">
        <bumperTopicName>BR_foot_contact_sensor_state</bumperTopicName>
        <frameName>BR_foot</frameName>
      </plugin>
    </sensor>
  </gazebo>
  <link name="CL_coxa_link">
    <visual>
      <geometry>
        <mesh filename="package://phantomx_description/meshes/coxa_link.STL"/>
      </geometry>
      <origin rpy="0 0 0" xyz="0 0 0"/>
      <material name="black"/>
    </visual>
    <collision>
      <geometry>
        <mesh filename="package://phantomx_description/meshes/coxa_link_simple.STL"/>
      </geometry>
      <origin rpy="0 0 0" xyz="0 0 0"/>
    </collision>
    <inertial>
      <origin xyz="0.024001547 0 0"/>
      <mass value="0.01096414"/>
      <inertia ixx="0.01" ixy="0.0" ixz="0.0" iyy="0.01" iyz="0.0" izz="0.01"/>
    </inertial>
  </link>
  <link name="CL_femur_link">
    <visual>
      <geometry>
        <mesh filename="package://phantomx_description/meshes/femur_link.STL"/>
      </geometry>
      <origin rpy="0 0 0" xyz="0 0 0"/>
      <material name="black"/>
    </visual>
    <collision>
      <geometry>
        <mesh filename="package://phantomx_description/meshes/femur_link_simple.STL"/>
      </geometry>
      <origin rpy="0 0 0" xyz="0 0 0"/>
    </collision>
    <inertial>
      <origin xyz="0.04208275 0.00000123 -0.00098111"/>
      <mass value="0.12147677"/>
      <inertia ixx="0.01" ixy="0.0" ixz="0" iyy="0.01" iyz="0.0" izz="0.01"/>
    </inertial>
  </link>
  <link name="CL_tibia_link">
    <visual>
      <geometry>
        <mesh filename="package://phantomx_description/meshes/tibia_link.STL"/>
      </geometry>
      <origin rpy="0 0 0" xyz="0 0 0"/>
      <material name="black"/>
    </visual>
    <collision>
      <geometry>
        <mesh filename="package://phantomx_description/meshes/tibia_link_simple.STL"/>
      </geometry>
      <origin rpy="0 0 0" xyz="0 0 0"/>
    </collision>
    <inertial>
      <origin xyz="0.05151483 0 0"/>
      <mass value="0.03741374"/>
      <inertia ixx="0.01" ixy="0.0" ixz="0.0" iyy="0.01" iyz="0.0" izz="0.01"/>
    </inertial>
  </link>
  <link name="CL_foot_link"/>
  <joint name="CL_coxa_joint" type="revolute">
    <parent link="base_link"/>
    <child link="CL_coxa_link"/>
    <limit effort="1000.0" lower="-3.14" upper="3.14" velocity="1.0"/>
    <axis xyz="0 0 1"/>
    <origin rpy="0 0 2.3561944905" xyz="-0.12 0.06 0"/>
    <dynamics damping="1.5" friction="1.5"/>
  </joint>
  <joint name="CL_femur_joint" type="revolute">
    <parent link="CL_coxa_link"/>
    <child link="CL_femur_link"/>
    <limit effort="1000.0" lower="-1.5707" upper="1.5707" velocity="1.0"/>
    <axis xyz="0 0 -1"/>
    <origin rpy="1.5707 0 0" xyz="0.048 0 0"/>
    <dynamics damping="1.5" friction="1.5"/>
  </joint>
  <joint name="CL_tibia_joint" type="revolute">
    <parent link="CL_femur_link"/>
    <child link="CL_tibia_link"/>
    <limit effort="1000.0" lower="-2.3562" upper="2.3562" velocity="1.0"/>
    <axis xyz="0 0 1"/>
    <origin rpy="0 0 -1.570796327" xyz="0.083 0 0"/>
    <dynamics damping="1.5" friction="1.5"/>
  </joint>
  <joint name="CL_foot_joint" type="fixed">
    <parent link="CL_tibia_link"/>
    <child link="CL_foot_link"/>
    <limit effort="1000.0" lower="-2.3562" upper="2.3562" velocity="1.0"/>
    <axis xyz="1 0 0"/>
    <origin rpy="0 0 0" xyz="0.143 0 0"/>
  </joint>
  <transmission name="tran_CL_coxa">
    <type>transmission_interface/SimpleTransmission</type>
    <joint name="CL_coxa_joint">
      <hardwareInterface>hardware_interface/EffortJointInterface</hardwareInterface>
    </joint>
    <actuator name="motor_CL_coxa">
      <hardwareInterface>hardware_interface/EffortJointInterface</hardwareInterface>
      <mechanicalReduction>50</mechanicalReduction>
    </actuator>
  </transmission>
  <transmission name="tran_CL_femur">
    <type>transmission_interface/SimpleTransmission</type>
    <joint name="CL_femur_joint">
      <hardwareInterface>hardware_interface/EffortJointInterface</hardwareInterface>
    </joint>
    <actuator name="motor_CL_femur">
      <hardwareInterface>hardware_interface/EffortJointInterface</hardwareInterface>
      <mechanicalReduction>50</mechanicalReduction>
    </actuator>
  </transmission>
  <transmission name="tran_CL_tibia">
    <type>transmission_interface/SimpleTransmission</type>
    <joint name="CL_tibia_joint">
      <hardwareInterface>hardware_interface/EffortJointInterface</hardwareInterface>
    </joint>
    <actuator name="motor_CL_tibia">
      <hardwareInterface>hardware_interface/EffortJointInterface</hardwareInterface>
      <mechanicalReduction>50</mechanicalReduction>
    </actuator>
  </transmission>
  <gazebo reference="CL_coxa_link">
    <material>Gazebo/Black</material>
    <mu1>0.8</mu1>
    <mu2>0.6</mu2>
    <kp>100</kp>
    <kd>10</kd>
    <gravity>True</gravity>
  </gazebo>
  <gazebo reference="CL_femur_link">
    <material>Gazebo/Black</material>
    <mu1>0.8</mu1>
    <mu2>0.6</mu2>
    <kp>100</kp>
    <kd>10</kd>
    <gravity>True</gravity>
  </gazebo>
  <gazebo reference="CL_tibia_link">
    <material>Gazebo/Black</material>
    <mu1>0.8</mu1>
    <mu2>0.6</mu2>
    <kp>1000</kp>
    <kd>100</kd>
    <gravity>True</gravity>
  </gazebo>
  <gazebo reference="CL_tibia_link">
    <sensor name="CL_foot_contact_sensor" type="contact">
      <always_on>true</always_on>
      <update_rate>30</update_rate>
      <contact>
        <collision>CL_collision</collision>
      </contact>
      <plugin filename="libgazebo_ros_bumper.so" name="gripper_bumper">
        <bumperTopicName>CL_foot_contact_sensor_state</bumperTopicName>
        <frameName>CL_foot</frameName>
      </plugin>
    </sensor>
  </gazebo>
  <link name="CR_coxa_link">
    <visual>
      <geometry>
        <mesh filename="package://phantomx_description/meshes/coxa_link.STL"/>
      </geometry>
      <origin rpy="0 0 0" xyz="0 0 0"/>
      <material name="black"/>
    </visual>
    <collision>
      <geometry>
        <mesh filename="package://phantomx_description/meshes/coxa_link_simple.STL"/>
      </geometry>
      <origin rpy="0 0 0" xyz="0 0 0"/>
    </collision>
    <inertial>
      <origin xyz="0.024001547 0 0"/>
      <mass value="0.01096414"/>
      <inertia ixx="0.01" ixy="0.0" ixz="0.0" iyy="0.01" iyz="0.0" izz="0.01"/>
    </inertial>
  </link>
  <link name="CR_femur_link">
    <visual>
      <geometry>
        <mesh filename="package://phantomx_description/meshes/femur_link.STL"/>
      </geometry>
      <origin rpy="0 0 0" xyz="0 0 0"/>
      <material name="black"/>
    </visual>
    <collision>
      <geometry>
        <mesh filename="package://phantomx_description/meshes/femur_link_simple.STL"/>
      </geometry>
      <origin rpy="0 0 0" xyz="0 0 0"/>
    </collision>
    <inertial>
      <origin xyz="0.04208275 0.00000123 -0.00098111"/>
      <mass value="0.12147677"/>
      <inertia ixx="0.01" ixy="0.0" ixz="0" iyy="0.01" iyz="0.0" izz="0.01"/>
    </inertial>
  </link>
  <link name="CR_tibia_link">
    <visual>
      <geometry>
        <mesh filename="package://phantomx_description/meshes/tibia_link.STL"/>
      </geometry>
      <origin rpy="0 0 0" xyz="0 0 0"/>
      <material name="black"/>
    </visual>
    <collision>
      <geometry>
        <mesh filename="package://phantomx_description/meshes/tibia_link_simple.STL"/>
      </geometry>
      <origin rpy="0 0 0" xyz="0 0 0"/>
    </collision>
    <inertial>
      <origin xyz="0.05151483 0 0"/>
      <mass value="0.03741374"/>
      <inertia ixx="0.01" ixy="0.0" ixz="0.0" iyy="0.01" iyz="0.0" izz="0.01"/>
    </inertial>
  </link>
  <link name="CR_foot_link"/>
  <joint name="CR_coxa_joint" type="revolute">
    <parent link="base_link"/>
    <child link="CR_coxa_link"/>
    <limit effort="1000.0" lower="-3.14" upper="3.14" velocity="1.0"/>
    <axis xyz="0 0 1"/>
    <origin rpy="0 0 -2.3561944905" xyz="-0.12 -0.06 0"/>
    <dynamics damping="1.5" friction="1.5"/>
  </joint>
  <joint name="CR_femur_joint" type="revolute">
    <parent link="CR_coxa_link"/>
    <child link="CR_femur_link"/>
    <limit effort="1000.0" lower="-1.5707" upper="1.5707" velocity="1.0"/>
    <axis xyz="0 0 1"/>
    <origin rpy="1.5707 0 0" xyz="0.048 0 0"/>
    <dynamics damping="1.5" friction="1.5"/>
  </joint>
  <joint name="CR_tibia_joint" type="revolute">
    <parent link="CR_femur_link"/>
    <child link="CR_tibia_link"/>
    <limit effort="1000.0" lower="-2.3562" upper="2.3562" velocity="1.0"/>
    <axis xyz="0 0 -1"/>
    <origin rpy="0 0 -1.570796327" xyz="0.083 0 0"/>
    <dynamics damping="1.5" friction="1.5"/>
  </joint>
  <joint name="CR_foot_joint" type="fixed">
    <parent link="CR_tibia_link"/>
    <child link="CR_foot_link"/>
    <limit effort="1000.0" lower="-2.3562" upper="2.3562" velocity="1.0"/>
    <axis xyz="1 0 0"/>
    <origin rpy="0 0 0" xyz="0.143 0 0"/>
  </joint>
  <transmission name="tran_CR_coxa">
    <type>transmission_interface/SimpleTransmission</type>
    <joint name="CR_coxa_joint">
      <hardwareInterface>hardware_interface/EffortJointInterface</hardwareInterface>
    </joint>
    <actuator name="motor_CR_coxa">
      <hardwareInterface>hardware_interface/EffortJointInterface</hardwareInterface>
      <mechanicalReduction>50</mechanicalReduction>
    </actuator>
  </transmission>
  <transmission name="tran_CR_femur">
    <type>transmission_interface/SimpleTransmission</type>
    <joint name="CR_femur_joint">
      <hardwareInterface>hardware_interface/EffortJointInterface</hardwareInterface>
    </joint>
    <actuator name="motor_CR_femur">
      <hardwareInterface>hardware_interface/EffortJointInterface</hardwareInterface>
      <mechanicalReduction>50</mechanicalReduction>
    </actuator>
  </transmission>
  <transmission name="tran_CR_tibia">
    <type>transmission_interface/SimpleTransmission</type>
    <joint name="CR_tibia_joint">
      <hardwareInterface>hardware_interface/EffortJointInterface</hardwareInterface>
    </joint>
    <actuator name="motor_CR_tibia">
      <hardwareInterface>hardware_interface/EffortJointInterface</hardwareInterface>
      <mechanicalReduction>50</mechanicalReduction>
    </actuator>
  </transmission>
  <gazebo reference="CR_coxa_link">
    <material>Gazebo/Black</material>
    <mu1>0.8</mu1>
    <mu2>0.6</mu2>
    <kp>100</kp>
    <kd>10</kd>
    <gravity>True</gravity>
  </gazebo>
  <gazebo reference="CR_femur_link">
    <material>Gazebo/Black</material>
    <mu1>0.8</mu1>
    <mu2>0.6</mu2>
    <kp>100</kp>
    <kd>10</kd>
    <gravity>True</gravity>
  </gazebo>
  <gazebo reference="CR_tibia_link">
    <material>Gazebo/Black</material>
    <mu1>0.8</mu1>
    <mu2>0.6</mu2>
    <kp>1000</kp>
    <kd>100</kd>
    <gravity>True</gravity>
  </gazebo>
  <gazebo reference="CR_tibia_link">
    <sensor name="CR_foot_contact_sensor" type="contact">
      <always_on>true</always_on>
      <update_rate>30</update_rate>
      <contact>
        <collision>CR_collision</collision>
      </contact>
      <plugin filename="libgazebo_ros_bumper.so" name="gripper_bumper">
        <bumperTopicName>CR_foot_contact_sensor_state</bumperTopicName>
        <frameName>CR_foot</frameName>
      </plugin>
    </sensor>
  </gazebo>
</robot>

