<sdf version='1.6'>
  <model name='phantomx'>
    <link name='root_link'>
      <pose frame=''>0 0 0 0 -0 0</pose>
      <inertial>
        <pose frame=''>0.009297 0 0.009297 0 -0 0</pose>
        <mass>1.0756</mass>
        <inertia>
          <ixx>3.11009</ixx>
          <ixy>-0.254602</ixy>
          <ixz>2.03091</ixz>
          <iyy>6.38159</iyy>
          <iyz>0.164179</iyz>
          <izz>5.33355</izz>
        </inertia>
      </inertial>
      <collision name='root_link_fixed_joint_lump__base_link_collision'>
        <pose frame=''>0 0 0 0 -0 0</pose>
        <geometry>
          <mesh>
            <scale>1 1 1</scale>
            <uri>model://phantomx_description/meshes/base_link_simple.stl</uri>
          </mesh>
        </geometry>
        <surface>
          <contact>
            <ode/>
          </contact>
          <friction>
            <ode/>
          </friction>
        </surface>
      </collision>
      <collision name='root_link_fixed_joint_lump__kinect_link_collision_1'>
        <pose frame=''>0.1 0 0.1 0 0.6 0</pose>
        <geometry>
          <box>
            <size>0.05 0.2 0.05</size>
          </box>
        </geometry>
        <surface>
          <contact>
            <ode/>
          </contact>
          <friction>
            <ode/>
          </friction>
        </surface>
      </collision>
      <visual name='root_link_fixed_joint_lump__base_link_visual'>
        <pose frame=''>0 0 0 0 -0 0</pose>
        <geometry>
          <mesh>
            <scale>1 1 1</scale>
            <uri>model://phantomx_description/meshes/base_link.stl</uri>
          </mesh>
        </geometry>
        <material>
          <script>
            <name>Gazebo/Black</name>
            <uri>file://media/materials/scripts/gazebo.material</uri>
          </script>
        </material>
      </visual>
      <visual name='root_link_fixed_joint_lump__kinect_link_visual_1'>
        <pose frame=''>0.1 0 0.1 0 0.6 0</pose>
        <geometry>
          <box>
            <size>0.05 0.2 0.05</size>
          </box>
        </geometry>
        <material>
          <script>
            <uri>__default__</uri>
            <name>__default__</name>
          </script>
        </material>
      </visual>
      <velocity_decay/>
      <gravity>1</gravity>
      <velocity_decay/>
      <sensor name='camera_1' type='depth'>
        <always_on>1</always_on>
        <visualize>1</visualize>
        <camera name='__default__'>
          <horizontal_fov>1.047</horizontal_fov>
          <image>
            <width>640</width>
            <height>480</height>
            <format>R8G8B8</format>
          </image>
          <depth_camera>
            <output>depths</output>
          </depth_camera>
          <clip>
            <near>0.1</near>
            <far>100</far>
          </clip>
        </camera>
        <plugin name='camera_controller' filename='libgazebo_ros_openni_kinect.so'>
          <alwaysOn>true</alwaysOn>
          <updateRate>10.0</updateRate>
          <cameraName>kinect</cameraName>
          <frameName>camera_link_optical</frameName>
          <imageTopicName>rgb/image_raw</imageTopicName>
          <depthImageTopicName>depth/image_raw</depthImageTopicName>
          <pointCloudTopicName>depth/points</pointCloudTopicName>
          <cameraInfoTopicName>rgb/camera_info</cameraInfoTopicName>
          <depthImageCameraInfoTopicName>depht/camera_info</depthImageCameraInfoTopicName>
          <pointCloudCutoff>0.4</pointCloudCutoff>
          <hackBaseline>0.07</hackBaseline>
          <distortionK1>0.0</distortionK1>
          <distortionK2>0.0</distortionK2>
          <distortionK3>0.0</distortionK3>
          <distortionT1>0.0</distortionT1>
          <distortionT2>0.0</distortionT2>
          <CxPrime>0.0</CxPrime>
          <Cx>0.0</Cx>
          <Cy>0.0</Cy>
          <focalLength>0.0</focalLength>
        </plugin>
        <pose frame=''>0.1 0 0.1 0 0.6 0</pose>
      </sensor>
    </link>
    <link name='AL_coxa_link'>
      <pose frame=''>0.12 0.06 0 0 -0 0.785398</pose>
      <inertial>
        <pose frame=''>0.024002 0 0 0 -0 0</pose>
        <mass>0.0109641</mass>
        <inertia>
          <ixx>0.01</ixx>
          <ixy>0</ixy>
          <ixz>0</ixz>
          <iyy>0.01</iyy>
          <iyz>0</iyz>
          <izz>0.01</izz>
        </inertia>
      </inertial>
      <collision name='AL_coxa_link_collision'>
        <pose frame=''>0 0 0 0 -0 0</pose>
        <geometry>
          <mesh>
            <scale>1 1 1</scale>
            <uri>model://phantomx_description/meshes/coxa_link_simple.STL</uri>
          </mesh>
        </geometry>
        <surface>
          <contact>
            <ode>
              <kp>100</kp>
              <kd>10</kd>
            </ode>
          </contact>
          <friction>
            <ode>
              <mu>0.8</mu>
              <mu2>0.6</mu2>
            </ode>
          </friction>
        </surface>
      </collision>
      <visual name='AL_coxa_link_visual'>
        <pose frame=''>0 0 0 0 -0 0</pose>
        <geometry>
          <mesh>
            <scale>1 1 1</scale>
            <uri>model://phantomx_description/meshes/coxa_link.STL</uri>
          </mesh>
        </geometry>
        <material>
          <script>
            <name>Gazebo/Black</name>
            <uri>file://media/materials/scripts/gazebo.material</uri>
          </script>
        </material>
      </visual>
      <gravity>1</gravity>
      <velocity_decay/>
      <gravity>1</gravity>
    </link>
    <joint name='AL_coxa_joint' type='revolute'>
      <child>AL_coxa_link</child>
      <parent>root_link</parent>
      <axis>
        <xyz>0 0 1</xyz>
        <limit>
          <lower>-3.14</lower>
          <upper>3.14</upper>
          <effort>1000</effort>
          <velocity>1</velocity>
        </limit>
        <dynamics>
          <damping>1.5</damping>
          <friction>1.5</friction>
          <spring_reference>0</spring_reference>
          <spring_stiffness>0</spring_stiffness>
        </dynamics>
        <use_parent_model_frame>1</use_parent_model_frame>
      </axis>
    </joint>
    <link name='AL_femur_link'>
      <pose frame=''>0.153941 0.093941 0 1.5707 -0 0.785398</pose>
      <inertial>
        <pose frame=''>0.042083 1e-06 -0.000981 0 -0 0</pose>
        <mass>0.121477</mass>
        <inertia>
          <ixx>0.01</ixx>
          <ixy>0</ixy>
          <ixz>0</ixz>
          <iyy>0.01</iyy>
          <iyz>0</iyz>
          <izz>0.01</izz>
        </inertia>
      </inertial>
      <collision name='AL_femur_link_collision'>
        <pose frame=''>0 0 0 0 -0 0</pose>
        <geometry>
          <mesh>
            <scale>1 1 1</scale>
            <uri>model://phantomx_description/meshes/femur_link_simple.STL</uri>
          </mesh>
        </geometry>
        <surface>
          <contact>
            <ode>
              <kp>100</kp>
              <kd>10</kd>
            </ode>
          </contact>
          <friction>
            <ode>
              <mu>0.8</mu>
              <mu2>0.6</mu2>
            </ode>
          </friction>
        </surface>
      </collision>
      <visual name='AL_femur_link_visual'>
        <pose frame=''>0 0 0 0 -0 0</pose>
        <geometry>
          <mesh>
            <scale>1 1 1</scale>
            <uri>model://phantomx_description/meshes/femur_link.STL</uri>
          </mesh>
        </geometry>
        <material>
          <script>
            <name>Gazebo/Black</name>
            <uri>file://media/materials/scripts/gazebo.material</uri>
          </script>
        </material>
      </visual>
      <gravity>1</gravity>
      <velocity_decay/>
      <gravity>1</gravity>
    </link>
    <joint name='AL_femur_joint' type='revolute'>
      <child>AL_femur_link</child>
      <parent>AL_coxa_link</parent>
      <axis>
        <xyz>-0.707107 0.707107 -9.6e-05</xyz>
        <limit>
          <lower>-1.5707</lower>
          <upper>1.5707</upper>
          <effort>1000</effort>
          <velocity>1</velocity>
        </limit>
        <dynamics>
          <damping>1.5</damping>
          <friction>1.5</friction>
          <spring_reference>0</spring_reference>
          <spring_stiffness>0</spring_stiffness>
        </dynamics>
        <use_parent_model_frame>1</use_parent_model_frame>
      </axis>
    </joint>
    <link name='AL_tibia_link'>
      <pose frame=''>0.212631 0.152631 -0 -2e-06 1.5707 -0.7854</pose>
      <inertial>
        <pose frame=''>0.051515 0 0 0 -0 0</pose>
        <mass>0.0374137</mass>
        <inertia>
          <ixx>0.01</ixx>
          <ixy>0</ixy>
          <ixz>0</ixz>
          <iyy>0.01</iyy>
          <iyz>0</iyz>
          <izz>0.01</izz>
        </inertia>
      </inertial>
      <collision name='AL_tibia_link_collision'>
        <pose frame=''>0 0 0 0 -0 0</pose>
        <geometry>
          <mesh>
            <scale>1 1 1</scale>
            <uri>model://phantomx_description/meshes/tibia_link_simple.STL</uri>
          </mesh>
        </geometry>
        <surface>
          <contact>
            <ode>
              <kp>1000</kp>
              <kd>100</kd>
            </ode>
          </contact>
          <friction>
            <ode>
              <mu>0.8</mu>
              <mu2>0.6</mu2>
            </ode>
          </friction>
        </surface>
      </collision>
      <visual name='AL_tibia_link_visual'>
        <pose frame=''>0 0 0 0 -0 0</pose>
        <geometry>
          <mesh>
            <scale>1 1 1</scale>
            <uri>model://phantomx_description/meshes/tibia_link.STL</uri>
          </mesh>
        </geometry>
        <material>
          <script>
            <name>Gazebo/Black</name>
            <uri>file://media/materials/scripts/gazebo.material</uri>
          </script>
        </material>
      </visual>
      <velocity_decay/>
      <gravity>1</gravity>
      <gravity>1</gravity>
      <velocity_decay/>
      <sensor name='AL_foot_contact_sensor' type='contact'>
        <always_on>1</always_on>
        <update_rate>30</update_rate>
        <contact>
          <collision>AL_collision</collision>
          <topic>__default_topic__</topic>
        </contact>
        <plugin name='gripper_bumper' filename='libgazebo_ros_bumper.so'>
          <bumperTopicName>AL_foot_contact_sensor_state</bumperTopicName>
          <frameName>AL_foot</frameName>
        </plugin>
      </sensor>
    </link>
    <joint name='AL_tibia_joint' type='revolute'>
      <child>AL_tibia_link</child>
      <parent>AL_femur_link</parent>
      <axis>
        <xyz>0.707107 -0.707107 9.6e-05</xyz>
        <limit>
          <lower>-2.3562</lower>
          <upper>2.3562</upper>
          <effort>1000</effort>
          <velocity>1</velocity>
        </limit>
        <dynamics>
          <damping>1.5</damping>
          <friction>1.5</friction>
          <spring_reference>0</spring_reference>
          <spring_stiffness>0</spring_stiffness>
        </dynamics>
        <use_parent_model_frame>1</use_parent_model_frame>
      </axis>
    </joint>
    <link name='AR_coxa_link'>
      <pose frame=''>0.12 -0.06 0 0 0 -0.785398</pose>
      <inertial>
        <pose frame=''>0.024002 0 0 0 -0 0</pose>
        <mass>0.0109641</mass>
        <inertia>
          <ixx>0.01</ixx>
          <ixy>0</ixy>
          <ixz>0</ixz>
          <iyy>0.01</iyy>
          <iyz>0</iyz>
          <izz>0.01</izz>
        </inertia>
      </inertial>
      <collision name='AR_coxa_link_collision'>
        <pose frame=''>0 0 0 0 -0 0</pose>
        <geometry>
          <mesh>
            <scale>1 1 1</scale>
            <uri>model://phantomx_description/meshes/coxa_link_simple.STL</uri>
          </mesh>
        </geometry>
        <surface>
          <contact>
            <ode>
              <kp>100</kp>
              <kd>10</kd>
            </ode>
          </contact>
          <friction>
            <ode>
              <mu>0.8</mu>
              <mu2>0.6</mu2>
            </ode>
          </friction>
        </surface>
      </collision>
      <visual name='AR_coxa_link_visual'>
        <pose frame=''>0 0 0 0 -0 0</pose>
        <geometry>
          <mesh>
            <scale>1 1 1</scale>
            <uri>model://phantomx_description/meshes/coxa_link.STL</uri>
          </mesh>
        </geometry>
        <material>
          <script>
            <name>Gazebo/Black</name>
            <uri>file://media/materials/scripts/gazebo.material</uri>
          </script>
        </material>
      </visual>
      <gravity>1</gravity>
      <velocity_decay/>
      <gravity>1</gravity>
    </link>
    <joint name='AR_coxa_joint' type='revolute'>
      <child>AR_coxa_link</child>
      <parent>root_link</parent>
      <axis>
        <xyz>0 0 1</xyz>
        <limit>
          <lower>-3.14</lower>
          <upper>3.14</upper>
          <effort>1000</effort>
          <velocity>1</velocity>
        </limit>
        <dynamics>
          <damping>1.5</damping>
          <friction>1.5</friction>
          <spring_reference>0</spring_reference>
          <spring_stiffness>0</spring_stiffness>
        </dynamics>
        <use_parent_model_frame>1</use_parent_model_frame>
      </axis>
    </joint>
    <link name='AR_femur_link'>
      <pose frame=''>0.153941 -0.093941 0 1.5707 -0 -0.785398</pose>
      <inertial>
        <pose frame=''>0.042083 1e-06 -0.000981 0 -0 0</pose>
        <mass>0.121477</mass>
        <inertia>
          <ixx>0.01</ixx>
          <ixy>0</ixy>
          <ixz>0</ixz>
          <iyy>0.01</iyy>
          <iyz>0</iyz>
          <izz>0.01</izz>
        </inertia>
      </inertial>
      <collision name='AR_femur_link_collision'>
        <pose frame=''>0 0 0 0 -0 0</pose>
        <geometry>
          <mesh>
            <scale>1 1 1</scale>
            <uri>model://phantomx_description/meshes/femur_link_simple.STL</uri>
          </mesh>
        </geometry>
        <surface>
          <contact>
            <ode>
              <kp>100</kp>
              <kd>10</kd>
            </ode>
          </contact>
          <friction>
            <ode>
              <mu>0.8</mu>
              <mu2>0.6</mu2>
            </ode>
          </friction>
        </surface>
      </collision>
      <visual name='AR_femur_link_visual'>
        <pose frame=''>0 0 0 0 -0 0</pose>
        <geometry>
          <mesh>
            <scale>1 1 1</scale>
            <uri>model://phantomx_description/meshes/femur_link.STL</uri>
          </mesh>
        </geometry>
        <material>
          <script>
            <name>Gazebo/Black</name>
            <uri>file://media/materials/scripts/gazebo.material</uri>
          </script>
        </material>
      </visual>
      <gravity>1</gravity>
      <velocity_decay/>
      <gravity>1</gravity>
    </link>
    <joint name='AR_femur_joint' type='revolute'>
      <child>AR_femur_link</child>
      <parent>AR_coxa_link</parent>
      <axis>
        <xyz>-0.707107 -0.707107 9.6e-05</xyz>
        <limit>
          <lower>-1.5707</lower>
          <upper>1.5707</upper>
          <effort>1000</effort>
          <velocity>1</velocity>
        </limit>
        <dynamics>
          <damping>1.5</damping>
          <friction>1.5</friction>
          <spring_reference>0</spring_reference>
          <spring_stiffness>0</spring_stiffness>
        </dynamics>
        <use_parent_model_frame>1</use_parent_model_frame>
      </axis>
    </joint>
    <link name='AR_tibia_link'>
      <pose frame=''>0.212631 -0.152631 0 -2e-06 1.5707 -2.3562</pose>
      <inertial>
        <pose frame=''>0.051515 0 0 0 -0 0</pose>
        <mass>0.0374137</mass>
        <inertia>
          <ixx>0.01</ixx>
          <ixy>0</ixy>
          <ixz>0</ixz>
          <iyy>0.01</iyy>
          <iyz>0</iyz>
          <izz>0.01</izz>
        </inertia>
      </inertial>
      <collision name='AR_tibia_link_collision'>
        <pose frame=''>0 0 0 0 -0 0</pose>
        <geometry>
          <mesh>
            <scale>1 1 1</scale>
            <uri>model://phantomx_description/meshes/tibia_link_simple.STL</uri>
          </mesh>
        </geometry>
        <surface>
          <contact>
            <ode>
              <kp>1000</kp>
              <kd>100</kd>
            </ode>
          </contact>
          <friction>
            <ode>
              <mu>0.8</mu>
              <mu2>0.6</mu2>
            </ode>
          </friction>
        </surface>
      </collision>
      <visual name='AR_tibia_link_visual'>
        <pose frame=''>0 0 0 0 -0 0</pose>
        <geometry>
          <mesh>
            <scale>1 1 1</scale>
            <uri>model://phantomx_description/meshes/tibia_link.STL</uri>
          </mesh>
        </geometry>
        <material>
          <script>
            <name>Gazebo/Black</name>
            <uri>file://media/materials/scripts/gazebo.material</uri>
          </script>
        </material>
      </visual>
      <velocity_decay/>
      <gravity>1</gravity>
      <gravity>1</gravity>
      <velocity_decay/>
      <sensor name='AR_foot_contact_sensor' type='contact'>
        <always_on>1</always_on>
        <update_rate>30</update_rate>
        <contact>
          <collision>AR_collision</collision>
          <topic>__default_topic__</topic>
        </contact>
        <plugin name='gripper_bumper' filename='libgazebo_ros_bumper.so'>
          <bumperTopicName>AR_foot_contact_sensor_state</bumperTopicName>
          <frameName>AR_foot</frameName>
        </plugin>
      </sensor>
    </link>
    <joint name='AR_tibia_joint' type='revolute'>
      <child>AR_tibia_link</child>
      <parent>AR_femur_link</parent>
      <axis>
        <xyz>0.707107 0.707107 -9.6e-05</xyz>
        <limit>
          <lower>-2.3562</lower>
          <upper>2.3562</upper>
          <effort>1000</effort>
          <velocity>1</velocity>
        </limit>
        <dynamics>
          <damping>1.5</damping>
          <friction>1.5</friction>
          <spring_reference>0</spring_reference>
          <spring_stiffness>0</spring_stiffness>
        </dynamics>
        <use_parent_model_frame>1</use_parent_model_frame>
      </axis>
    </joint>
    <link name='BL_coxa_link'>
      <pose frame=''>0 0.1 0 0 -0 1.5708</pose>
      <inertial>
        <pose frame=''>0.024002 0 0 0 -0 0</pose>
        <mass>0.0109641</mass>
        <inertia>
          <ixx>0.01</ixx>
          <ixy>0</ixy>
          <ixz>0</ixz>
          <iyy>0.01</iyy>
          <iyz>0</iyz>
          <izz>0.01</izz>
        </inertia>
      </inertial>
      <collision name='BL_coxa_link_collision'>
        <pose frame=''>0 0 0 0 -0 0</pose>
        <geometry>
          <mesh>
            <scale>1 1 1</scale>
            <uri>model://phantomx_description/meshes/coxa_link_simple.STL</uri>
          </mesh>
        </geometry>
        <surface>
          <contact>
            <ode>
              <kp>100</kp>
              <kd>10</kd>
            </ode>
          </contact>
          <friction>
            <ode>
              <mu>0.8</mu>
              <mu2>0.6</mu2>
            </ode>
          </friction>
        </surface>
      </collision>
      <visual name='BL_coxa_link_visual'>
        <pose frame=''>0 0 0 0 -0 0</pose>
        <geometry>
          <mesh>
            <scale>1 1 1</scale>
            <uri>model://phantomx_description/meshes/coxa_link.STL</uri>
          </mesh>
        </geometry>
        <material>
          <script>
            <name>Gazebo/Black</name>
            <uri>file://media/materials/scripts/gazebo.material</uri>
          </script>
        </material>
      </visual>
      <gravity>1</gravity>
      <velocity_decay/>
      <gravity>1</gravity>
    </link>
    <joint name='BL_coxa_joint' type='revolute'>
      <child>BL_coxa_link</child>
      <parent>root_link</parent>
      <axis>
        <xyz>0 0 1</xyz>
        <limit>
          <lower>-3.14</lower>
          <upper>3.14</upper>
          <effort>1000</effort>
          <velocity>1</velocity>
        </limit>
        <dynamics>
          <damping>1.5</damping>
          <friction>1.5</friction>
          <spring_reference>0</spring_reference>
          <spring_stiffness>0</spring_stiffness>
        </dynamics>
        <use_parent_model_frame>1</use_parent_model_frame>
      </axis>
    </joint>
    <link name='BL_femur_link'>
      <pose frame=''>-0 0.148 0 1.5707 -0 1.5708</pose>
      <inertial>
        <pose frame=''>0.042083 1e-06 -0.000981 0 -0 0</pose>
        <mass>0.121477</mass>
        <inertia>
          <ixx>0.01</ixx>
          <ixy>0</ixy>
          <ixz>0</ixz>
          <iyy>0.01</iyy>
          <iyz>0</iyz>
          <izz>0.01</izz>
        </inertia>
      </inertial>
      <collision name='BL_femur_link_collision'>
        <pose frame=''>0 0 0 0 -0 0</pose>
        <geometry>
          <mesh>
            <scale>1 1 1</scale>
            <uri>model://phantomx_description/meshes/femur_link_simple.STL</uri>
          </mesh>
        </geometry>
        <surface>
          <contact>
            <ode>
              <kp>100</kp>
              <kd>10</kd>
            </ode>
          </contact>
          <friction>
            <ode>
              <mu>0.8</mu>
              <mu2>0.6</mu2>
            </ode>
          </friction>
        </surface>
      </collision>
      <visual name='BL_femur_link_visual'>
        <pose frame=''>0 0 0 0 -0 0</pose>
        <geometry>
          <mesh>
            <scale>1 1 1</scale>
            <uri>model://phantomx_description/meshes/femur_link.STL</uri>
          </mesh>
        </geometry>
        <material>
          <script>
            <name>Gazebo/Black</name>
            <uri>file://media/materials/scripts/gazebo.material</uri>
          </script>
        </material>
      </visual>
      <gravity>1</gravity>
      <velocity_decay/>
      <gravity>1</gravity>
    </link>
    <joint name='BL_femur_joint' type='revolute'>
      <child>BL_femur_link</child>
      <parent>BL_coxa_link</parent>
      <axis>
        <xyz>-1 -0 -9.6e-05</xyz>
        <limit>
          <lower>-1.5707</lower>
          <upper>1.5707</upper>
          <effort>1000</effort>
          <velocity>1</velocity>
        </limit>
        <dynamics>
          <damping>1.5</damping>
          <friction>1.5</friction>
          <spring_reference>0</spring_reference>
          <spring_stiffness>0</spring_stiffness>
        </dynamics>
        <use_parent_model_frame>1</use_parent_model_frame>
      </axis>
    </joint>
    <link name='BL_tibia_link'>
      <pose frame=''>-0 0.231 -0 -2e-06 1.5707 -2e-06</pose>
      <inertial>
        <pose frame=''>0.051515 0 0 0 -0 0</pose>
        <mass>0.0374137</mass>
        <inertia>
          <ixx>0.01</ixx>
          <ixy>0</ixy>
          <ixz>0</ixz>
          <iyy>0.01</iyy>
          <iyz>0</iyz>
          <izz>0.01</izz>
        </inertia>
      </inertial>
      <collision name='BL_tibia_link_collision'>
        <pose frame=''>0 0 0 0 -0 0</pose>
        <geometry>
          <mesh>
            <scale>1 1 1</scale>
            <uri>model://phantomx_description/meshes/tibia_link_simple.STL</uri>
          </mesh>
        </geometry>
        <surface>
          <contact>
            <ode>
              <kp>1000</kp>
              <kd>100</kd>
            </ode>
          </contact>
          <friction>
            <ode>
              <mu>0.8</mu>
              <mu2>0.6</mu2>
            </ode>
          </friction>
        </surface>
      </collision>
      <visual name='BL_tibia_link_visual'>
        <pose frame=''>0 0 0 0 -0 0</pose>
        <geometry>
          <mesh>
            <scale>1 1 1</scale>
            <uri>model://phantomx_description/meshes/tibia_link.STL</uri>
          </mesh>
        </geometry>
        <material>
          <script>
            <name>Gazebo/Black</name>
            <uri>file://media/materials/scripts/gazebo.material</uri>
          </script>
        </material>
      </visual>
      <velocity_decay/>
      <gravity>1</gravity>
      <gravity>1</gravity>
      <velocity_decay/>
      <sensor name='BL_foot_contact_sensor' type='contact'>
        <always_on>1</always_on>
        <update_rate>30</update_rate>
        <contact>
          <collision>BL_collision</collision>
          <topic>__default_topic__</topic>
        </contact>
        <plugin name='gripper_bumper' filename='libgazebo_ros_bumper.so'>
          <bumperTopicName>BL_foot_contact_sensor_state</bumperTopicName>
          <frameName>BL_foot</frameName>
        </plugin>
      </sensor>
    </link>
    <joint name='BL_tibia_joint' type='revolute'>
      <child>BL_tibia_link</child>
      <parent>BL_femur_link</parent>
      <axis>
        <xyz>1 0 9.6e-05</xyz>
        <limit>
          <lower>-2.3562</lower>
          <upper>2.3562</upper>
          <effort>1000</effort>
          <velocity>1</velocity>
        </limit>
        <dynamics>
          <damping>1.5</damping>
          <friction>1.5</friction>
          <spring_reference>0</spring_reference>
          <spring_stiffness>0</spring_stiffness>
        </dynamics>
        <use_parent_model_frame>1</use_parent_model_frame>
      </axis>
    </joint>
    <link name='BR_coxa_link'>
      <pose frame=''>0 -0.1 0 0 0 -1.5708</pose>
      <inertial>
        <pose frame=''>0.024002 0 0 0 -0 0</pose>
        <mass>0.0109641</mass>
        <inertia>
          <ixx>0.01</ixx>
          <ixy>0</ixy>
          <ixz>0</ixz>
          <iyy>0.01</iyy>
          <iyz>0</iyz>
          <izz>0.01</izz>
        </inertia>
      </inertial>
      <collision name='BR_coxa_link_collision'>
        <pose frame=''>0 0 0 0 -0 0</pose>
        <geometry>
          <mesh>
            <scale>1 1 1</scale>
            <uri>model://phantomx_description/meshes/coxa_link_simple.STL</uri>
          </mesh>
        </geometry>
        <surface>
          <contact>
            <ode>
              <kp>100</kp>
              <kd>10</kd>
            </ode>
          </contact>
          <friction>
            <ode>
              <mu>0.8</mu>
              <mu2>0.6</mu2>
            </ode>
          </friction>
        </surface>
      </collision>
      <visual name='BR_coxa_link_visual'>
        <pose frame=''>0 0 0 0 -0 0</pose>
        <geometry>
          <mesh>
            <scale>1 1 1</scale>
            <uri>model://phantomx_description/meshes/coxa_link.STL</uri>
          </mesh>
        </geometry>
        <material>
          <script>
            <name>Gazebo/Black</name>
            <uri>file://media/materials/scripts/gazebo.material</uri>
          </script>
        </material>
      </visual>
      <gravity>1</gravity>
      <velocity_decay/>
      <gravity>1</gravity>
    </link>
    <joint name='BR_coxa_joint' type='revolute'>
      <child>BR_coxa_link</child>
      <parent>root_link</parent>
      <axis>
        <xyz>0 0 1</xyz>
        <limit>
          <lower>-3.14</lower>
          <upper>3.14</upper>
          <effort>1000</effort>
          <velocity>1</velocity>
        </limit>
        <dynamics>
          <damping>1.5</damping>
          <friction>1.5</friction>
          <spring_reference>0</spring_reference>
          <spring_stiffness>0</spring_stiffness>
        </dynamics>
        <use_parent_model_frame>1</use_parent_model_frame>
      </axis>
    </joint>
    <link name='BR_femur_link'>
      <pose frame=''>-0 -0.148 0 1.5707 0 -1.5708</pose>
      <inertial>
        <pose frame=''>0.042083 1e-06 -0.000981 0 -0 0</pose>
        <mass>0.121477</mass>
        <inertia>
          <ixx>0.01</ixx>
          <ixy>0</ixy>
          <ixz>0</ixz>
          <iyy>0.01</iyy>
          <iyz>0</iyz>
          <izz>0.01</izz>
        </inertia>
      </inertial>
      <collision name='BR_femur_link_collision'>
        <pose frame=''>0 0 0 0 -0 0</pose>
        <geometry>
          <mesh>
            <scale>1 1 1</scale>
            <uri>model://phantomx_description/meshes/femur_link_simple.STL</uri>
          </mesh>
        </geometry>
        <surface>
          <contact>
            <ode>
              <kp>100</kp>
              <kd>10</kd>
            </ode>
          </contact>
          <friction>
            <ode>
              <mu>0.8</mu>
              <mu2>0.6</mu2>
            </ode>
          </friction>
        </surface>
      </collision>
      <visual name='BR_femur_link_visual'>
        <pose frame=''>0 0 0 0 -0 0</pose>
        <geometry>
          <mesh>
            <scale>1 1 1</scale>
            <uri>model://phantomx_description/meshes/femur_link.STL</uri>
          </mesh>
        </geometry>
        <material>
          <script>
            <name>Gazebo/Black</name>
            <uri>file://media/materials/scripts/gazebo.material</uri>
          </script>
        </material>
      </visual>
      <gravity>1</gravity>
      <velocity_decay/>
      <gravity>1</gravity>
    </link>
    <joint name='BR_femur_joint' type='revolute'>
      <child>BR_femur_link</child>
      <parent>BR_coxa_link</parent>
      <axis>
        <xyz>-1 0 9.6e-05</xyz>
        <limit>
          <lower>-1.5707</lower>
          <upper>1.5707</upper>
          <effort>1000</effort>
          <velocity>1</velocity>
        </limit>
        <dynamics>
          <damping>1.5</damping>
          <friction>1.5</friction>
          <spring_reference>0</spring_reference>
          <spring_stiffness>0</spring_stiffness>
        </dynamics>
        <use_parent_model_frame>1</use_parent_model_frame>
      </axis>
    </joint>
    <link name='BR_tibia_link'>
      <pose frame=''>-0 -0.231 0 -2e-06 1.5707 3.14159</pose>
      <inertial>
        <pose frame=''>0.051515 0 0 0 -0 0</pose>
        <mass>0.0374137</mass>
        <inertia>
          <ixx>0.01</ixx>
          <ixy>0</ixy>
          <ixz>0</ixz>
          <iyy>0.01</iyy>
          <iyz>0</iyz>
          <izz>0.01</izz>
        </inertia>
      </inertial>
      <collision name='BR_tibia_link_collision'>
        <pose frame=''>0 0 0 0 -0 0</pose>
        <geometry>
          <mesh>
            <scale>1 1 1</scale>
            <uri>model://phantomx_description/meshes/tibia_link_simple.STL</uri>
          </mesh>
        </geometry>
        <surface>
          <contact>
            <ode>
              <kp>1000</kp>
              <kd>100</kd>
            </ode>
          </contact>
          <friction>
            <ode>
              <mu>0.8</mu>
              <mu2>0.6</mu2>
            </ode>
          </friction>
        </surface>
      </collision>
      <visual name='BR_tibia_link_visual'>
        <pose frame=''>0 0 0 0 -0 0</pose>
        <geometry>
          <mesh>
            <scale>1 1 1</scale>
            <uri>model://phantomx_description/meshes/tibia_link.STL</uri>
          </mesh>
        </geometry>
        <material>
          <script>
            <name>Gazebo/Black</name>
            <uri>file://media/materials/scripts/gazebo.material</uri>
          </script>
        </material>
      </visual>
      <velocity_decay/>
      <gravity>1</gravity>
      <gravity>1</gravity>
      <velocity_decay/>
      <sensor name='BR_foot_contact_sensor' type='contact'>
        <always_on>1</always_on>
        <update_rate>30</update_rate>
        <contact>
          <collision>BR_collision</collision>
          <topic>__default_topic__</topic>
        </contact>
        <plugin name='gripper_bumper' filename='libgazebo_ros_bumper.so'>
          <bumperTopicName>BR_foot_contact_sensor_state</bumperTopicName>
          <frameName>BR_foot</frameName>
        </plugin>
      </sensor>
    </link>
    <joint name='BR_tibia_joint' type='revolute'>
      <child>BR_tibia_link</child>
      <parent>BR_femur_link</parent>
      <axis>
        <xyz>1 -0 -9.6e-05</xyz>
        <limit>
          <lower>-2.3562</lower>
          <upper>2.3562</upper>
          <effort>1000</effort>
          <velocity>1</velocity>
        </limit>
        <dynamics>
          <damping>1.5</damping>
          <friction>1.5</friction>
          <spring_reference>0</spring_reference>
          <spring_stiffness>0</spring_stiffness>
        </dynamics>
        <use_parent_model_frame>1</use_parent_model_frame>
      </axis>
    </joint>
    <link name='CL_coxa_link'>
      <pose frame=''>-0.12 0.06 0 0 -0 2.35619</pose>
      <inertial>
        <pose frame=''>0.024002 0 0 0 -0 0</pose>
        <mass>0.0109641</mass>
        <inertia>
          <ixx>0.01</ixx>
          <ixy>0</ixy>
          <ixz>0</ixz>
          <iyy>0.01</iyy>
          <iyz>0</iyz>
          <izz>0.01</izz>
        </inertia>
      </inertial>
      <collision name='CL_coxa_link_collision'>
        <pose frame=''>0 0 0 0 -0 0</pose>
        <geometry>
          <mesh>
            <scale>1 1 1</scale>
            <uri>model://phantomx_description/meshes/coxa_link_simple.STL</uri>
          </mesh>
        </geometry>
        <surface>
          <contact>
            <ode>
              <kp>100</kp>
              <kd>10</kd>
            </ode>
          </contact>
          <friction>
            <ode>
              <mu>0.8</mu>
              <mu2>0.6</mu2>
            </ode>
          </friction>
        </surface>
      </collision>
      <visual name='CL_coxa_link_visual'>
        <pose frame=''>0 0 0 0 -0 0</pose>
        <geometry>
          <mesh>
            <scale>1 1 1</scale>
            <uri>model://phantomx_description/meshes/coxa_link.STL</uri>
          </mesh>
        </geometry>
        <material>
          <script>
            <name>Gazebo/Black</name>
            <uri>file://media/materials/scripts/gazebo.material</uri>
          </script>
        </material>
      </visual>
      <gravity>1</gravity>
      <velocity_decay/>
      <gravity>1</gravity>
    </link>
    <joint name='CL_coxa_joint' type='revolute'>
      <child>CL_coxa_link</child>
      <parent>root_link</parent>
      <axis>
        <xyz>0 0 1</xyz>
        <limit>
          <lower>-3.14</lower>
          <upper>3.14</upper>
          <effort>1000</effort>
          <velocity>1</velocity>
        </limit>
        <dynamics>
          <damping>1.5</damping>
          <friction>1.5</friction>
          <spring_reference>0</spring_reference>
          <spring_stiffness>0</spring_stiffness>
        </dynamics>
        <use_parent_model_frame>1</use_parent_model_frame>
      </axis>
    </joint>
    <link name='CL_femur_link'>
      <pose frame=''>-0.153941 0.093941 0 1.5707 -0 2.35619</pose>
      <inertial>
        <pose frame=''>0.042083 1e-06 -0.000981 0 -0 0</pose>
        <mass>0.121477</mass>
        <inertia>
          <ixx>0.01</ixx>
          <ixy>0</ixy>
          <ixz>0</ixz>
          <iyy>0.01</iyy>
          <iyz>0</iyz>
          <izz>0.01</izz>
        </inertia>
      </inertial>
      <collision name='CL_femur_link_collision'>
        <pose frame=''>0 0 0 0 -0 0</pose>
        <geometry>
          <mesh>
            <scale>1 1 1</scale>
            <uri>model://phantomx_description/meshes/femur_link_simple.STL</uri>
          </mesh>
        </geometry>
        <surface>
          <contact>
            <ode>
              <kp>100</kp>
              <kd>10</kd>
            </ode>
          </contact>
          <friction>
            <ode>
              <mu>0.8</mu>
              <mu2>0.6</mu2>
            </ode>
          </friction>
        </surface>
      </collision>
      <visual name='CL_femur_link_visual'>
        <pose frame=''>0 0 0 0 -0 0</pose>
        <geometry>
          <mesh>
            <scale>1 1 1</scale>
            <uri>model://phantomx_description/meshes/femur_link.STL</uri>
          </mesh>
        </geometry>
        <material>
          <script>
            <name>Gazebo/Black</name>
            <uri>file://media/materials/scripts/gazebo.material</uri>
          </script>
        </material>
      </visual>
      <gravity>1</gravity>
      <velocity_decay/>
      <gravity>1</gravity>
    </link>
    <joint name='CL_femur_joint' type='revolute'>
      <child>CL_femur_link</child>
      <parent>CL_coxa_link</parent>
      <axis>
        <xyz>-0.707107 -0.707107 -9.6e-05</xyz>
        <limit>
          <lower>-1.5707</lower>
          <upper>1.5707</upper>
          <effort>1000</effort>
          <velocity>1</velocity>
        </limit>
        <dynamics>
          <damping>1.5</damping>
          <friction>1.5</friction>
          <spring_reference>0</spring_reference>
          <spring_stiffness>0</spring_stiffness>
        </dynamics>
        <use_parent_model_frame>1</use_parent_model_frame>
      </axis>
    </joint>
    <link name='CL_tibia_link'>
      <pose frame=''>-0.212631 0.152631 0 -2e-06 1.5707 0.785396</pose>
      <inertial>
        <pose frame=''>0.051515 0 0 0 -0 0</pose>
        <mass>0.0374137</mass>
        <inertia>
          <ixx>0.01</ixx>
          <ixy>0</ixy>
          <ixz>0</ixz>
          <iyy>0.01</iyy>
          <iyz>0</iyz>
          <izz>0.01</izz>
        </inertia>
      </inertial>
      <collision name='CL_tibia_link_collision'>
        <pose frame=''>0 0 0 0 -0 0</pose>
        <geometry>
          <mesh>
            <scale>1 1 1</scale>
            <uri>model://phantomx_description/meshes/tibia_link_simple.STL</uri>
          </mesh>
        </geometry>
        <surface>
          <contact>
            <ode>
              <kp>1000</kp>
              <kd>100</kd>
            </ode>
          </contact>
          <friction>
            <ode>
              <mu>0.8</mu>
              <mu2>0.6</mu2>
            </ode>
          </friction>
        </surface>
      </collision>
      <visual name='CL_tibia_link_visual'>
        <pose frame=''>0 0 0 0 -0 0</pose>
        <geometry>
          <mesh>
            <scale>1 1 1</scale>
            <uri>model://phantomx_description/meshes/tibia_link.STL</uri>
          </mesh>
        </geometry>
        <material>
          <script>
            <name>Gazebo/Black</name>
            <uri>file://media/materials/scripts/gazebo.material</uri>
          </script>
        </material>
      </visual>
      <velocity_decay/>
      <gravity>1</gravity>
      <gravity>1</gravity>
      <velocity_decay/>
      <sensor name='CL_foot_contact_sensor' type='contact'>
        <always_on>1</always_on>
        <update_rate>30</update_rate>
        <contact>
          <collision>CL_collision</collision>
          <topic>__default_topic__</topic>
        </contact>
        <plugin name='gripper_bumper' filename='libgazebo_ros_bumper.so'>
          <bumperTopicName>CL_foot_contact_sensor_state</bumperTopicName>
          <frameName>CL_foot</frameName>
        </plugin>
      </sensor>
    </link>
    <joint name='CL_tibia_joint' type='revolute'>
      <child>CL_tibia_link</child>
      <parent>CL_femur_link</parent>
      <axis>
        <xyz>0.707107 0.707107 9.6e-05</xyz>
        <limit>
          <lower>-2.3562</lower>
          <upper>2.3562</upper>
          <effort>1000</effort>
          <velocity>1</velocity>
        </limit>
        <dynamics>
          <damping>1.5</damping>
          <friction>1.5</friction>
          <spring_reference>0</spring_reference>
          <spring_stiffness>0</spring_stiffness>
        </dynamics>
        <use_parent_model_frame>1</use_parent_model_frame>
      </axis>
    </joint>
    <link name='CR_coxa_link'>
      <pose frame=''>-0.12 -0.06 0 0 0 -2.35619</pose>
      <inertial>
        <pose frame=''>0.024002 0 0 0 -0 0</pose>
        <mass>0.0109641</mass>
        <inertia>
          <ixx>0.01</ixx>
          <ixy>0</ixy>
          <ixz>0</ixz>
          <iyy>0.01</iyy>
          <iyz>0</iyz>
          <izz>0.01</izz>
        </inertia>
      </inertial>
      <collision name='CR_coxa_link_collision'>
        <pose frame=''>0 0 0 0 -0 0</pose>
        <geometry>
          <mesh>
            <scale>1 1 1</scale>
            <uri>model://phantomx_description/meshes/coxa_link_simple.STL</uri>
          </mesh>
        </geometry>
        <surface>
          <contact>
            <ode>
              <kp>100</kp>
              <kd>10</kd>
            </ode>
          </contact>
          <friction>
            <ode>
              <mu>0.8</mu>
              <mu2>0.6</mu2>
            </ode>
          </friction>
        </surface>
      </collision>
      <visual name='CR_coxa_link_visual'>
        <pose frame=''>0 0 0 0 -0 0</pose>
        <geometry>
          <mesh>
            <scale>1 1 1</scale>
            <uri>model://phantomx_description/meshes/coxa_link.STL</uri>
          </mesh>
        </geometry>
        <material>
          <script>
            <name>Gazebo/Black</name>
            <uri>file://media/materials/scripts/gazebo.material</uri>
          </script>
        </material>
      </visual>
      <gravity>1</gravity>
      <velocity_decay/>
      <gravity>1</gravity>
    </link>
    <joint name='CR_coxa_joint' type='revolute'>
      <child>CR_coxa_link</child>
      <parent>root_link</parent>
      <axis>
        <xyz>0 0 1</xyz>
        <limit>
          <lower>-3.14</lower>
          <upper>3.14</upper>
          <effort>1000</effort>
          <velocity>1</velocity>
        </limit>
        <dynamics>
          <damping>1.5</damping>
          <friction>1.5</friction>
          <spring_reference>0</spring_reference>
          <spring_stiffness>0</spring_stiffness>
        </dynamics>
        <use_parent_model_frame>1</use_parent_model_frame>
      </axis>
    </joint>
    <link name='CR_femur_link'>
      <pose frame=''>-0.153941 -0.093941 0 1.5707 -0 -2.35619</pose>
      <inertial>
        <pose frame=''>0.042083 1e-06 -0.000981 0 -0 0</pose>
        <mass>0.121477</mass>
        <inertia>
          <ixx>0.01</ixx>
          <ixy>0</ixy>
          <ixz>0</ixz>
          <iyy>0.01</iyy>
          <iyz>0</iyz>
          <izz>0.01</izz>
        </inertia>
      </inertial>
      <collision name='CR_femur_link_collision'>
        <pose frame=''>0 0 0 0 -0 0</pose>
        <geometry>
          <mesh>
            <scale>1 1 1</scale>
            <uri>model://phantomx_description/meshes/femur_link_simple.STL</uri>
          </mesh>
        </geometry>
        <surface>
          <contact>
            <ode>
              <kp>100</kp>
              <kd>10</kd>
            </ode>
          </contact>
          <friction>
            <ode>
              <mu>0.8</mu>
              <mu2>0.6</mu2>
            </ode>
          </friction>
        </surface>
      </collision>
      <visual name='CR_femur_link_visual'>
        <pose frame=''>0 0 0 0 -0 0</pose>
        <geometry>
          <mesh>
            <scale>1 1 1</scale>
            <uri>model://phantomx_description/meshes/femur_link.STL</uri>
          </mesh>
        </geometry>
        <material>
          <script>
            <name>Gazebo/Black</name>
            <uri>file://media/materials/scripts/gazebo.material</uri>
          </script>
        </material>
      </visual>
      <gravity>1</gravity>
      <velocity_decay/>
      <gravity>1</gravity>
    </link>
    <joint name='CR_femur_joint' type='revolute'>
      <child>CR_femur_link</child>
      <parent>CR_coxa_link</parent>
      <axis>
        <xyz>-0.707107 0.707107 9.6e-05</xyz>
        <limit>
          <lower>-1.5707</lower>
          <upper>1.5707</upper>
          <effort>1000</effort>
          <velocity>1</velocity>
        </limit>
        <dynamics>
          <damping>1.5</damping>
          <friction>1.5</friction>
          <spring_reference>0</spring_reference>
          <spring_stiffness>0</spring_stiffness>
        </dynamics>
        <use_parent_model_frame>1</use_parent_model_frame>
      </axis>
    </joint>
    <link name='CR_tibia_link'>
      <pose frame=''>-0.212631 -0.152631 -0 -2e-06 1.5707 2.35619</pose>
      <inertial>
        <pose frame=''>0.051515 0 0 0 -0 0</pose>
        <mass>0.0374137</mass>
        <inertia>
          <ixx>0.01</ixx>
          <ixy>0</ixy>
          <ixz>0</ixz>
          <iyy>0.01</iyy>
          <iyz>0</iyz>
          <izz>0.01</izz>
        </inertia>
      </inertial>
      <collision name='CR_tibia_link_collision'>
        <pose frame=''>0 0 0 0 -0 0</pose>
        <geometry>
          <mesh>
            <scale>1 1 1</scale>
            <uri>model://phantomx_description/meshes/tibia_link_simple.STL</uri>
          </mesh>
        </geometry>
        <surface>
          <contact>
            <ode>
              <kp>1000</kp>
              <kd>100</kd>
            </ode>
          </contact>
          <friction>
            <ode>
              <mu>0.8</mu>
              <mu2>0.6</mu2>
            </ode>
          </friction>
        </surface>
      </collision>
      <visual name='CR_tibia_link_visual'>
        <pose frame=''>0 0 0 0 -0 0</pose>
        <geometry>
          <mesh>
            <scale>1 1 1</scale>
            <uri>model://phantomx_description/meshes/tibia_link.STL</uri>
          </mesh>
        </geometry>
        <material>
          <script>
            <name>Gazebo/Black</name>
            <uri>file://media/materials/scripts/gazebo.material</uri>
          </script>
        </material>
      </visual>
      <velocity_decay/>
      <gravity>1</gravity>
      <gravity>1</gravity>
      <velocity_decay/>
      <sensor name='CR_foot_contact_sensor' type='contact'>
        <always_on>1</always_on>
        <update_rate>30</update_rate>
        <contact>
          <collision>CR_collision</collision>
          <topic>__default_topic__</topic>
        </contact>
        <plugin name='gripper_bumper' filename='libgazebo_ros_bumper.so'>
          <bumperTopicName>CR_foot_contact_sensor_state</bumperTopicName>
          <frameName>CR_foot</frameName>
        </plugin>
      </sensor>
    </link>
    <joint name='CR_tibia_joint' type='revolute'>
      <child>CR_tibia_link</child>
      <parent>CR_femur_link</parent>
      <axis>
        <xyz>0.707107 -0.707107 -9.6e-05</xyz>
        <limit>
          <lower>-2.3562</lower>
          <upper>2.3562</upper>
          <effort>1000</effort>
          <velocity>1</velocity>
        </limit>
        <dynamics>
          <damping>1.5</damping>
          <friction>1.5</friction>
          <spring_reference>0</spring_reference>
          <spring_stiffness>0</spring_stiffness>
        </dynamics>
        <use_parent_model_frame>1</use_parent_model_frame>
      </axis>
    </joint>
    <static>0</static>
    <plugin name='gazebo_ros_control' filename='libgazebo_ros_control.so'>
      <robotSimType>gazebo_ros_control/DefaultRobotHWSim</robotSimType>
    </plugin>
  </model>
</sdf>
